Workbook

Sheet 📊 Dashboard
A1: 🏋️ Jo's Training Hub 2024–2026
A3: 💪 Gym Training | E3: 📊 Quick Stats
A4: Total sessions logged | B4: 6
A5: First session | B5: 19 Sep 2024
A6: Latest session | B6: 1 Jan 2026
A7: Body weight range | B7: 48.4 – 49.3 kg
A8: Exercise categories | B8: 5 (Inferior, Core, Superior, Wrist, Fingers)
A10: 📋 Sheets in this file:
A11: 💪 Gym Session Log | B11: → Log every session in a clean table
A12: 📈 Exercise Progress | B12: → Track weight progression per exercise
A13: 🦵 Rehab Program | B13: → Calf rehab programme (Dyllan / FisioHolland)
A14: 🧗 Climbing Log | B14: → Weekly climbing sessions & grade counts
A15: 🏔️ Climbing Goals | B15: → Pyramid targets & macrocycle plan
A16: 📅 Weekly Planner | B16: → Plan your training week
A18: 💡 How to use:
A19: 1. Log each gym session | B19: in 💪 Gym Session Log — add a new row per session
A20: 2. Check progress | B20: in 📈 Exercise Progress — weights auto-update
A21: 3. After rehab surgery | B21: follow the 🦵 Rehab Program week by week
A22: 4. After every climb | B22: log grades in 🧗 Climbing Log

Sheet Ref
A1: Exercise | B1: Category | C1: Sets | D1: Reps / Time | E1: Rest
A2: Hip Abductor | B2: Inferior Members | C2: 4 | D2: 6 | E2: 3'
A3: Hip Adductor | B3: Inferior Members | C3: 4 | D3: 6 | E3: 3'
A4: Ext. Quadriceps | B4: Inferior Members | C4: 4 | D4: 6 | E4: 3'
A5: Prone Leg Curl | B5: Inferior Members | C5: 3 | D5: 8 | E5: 3'
A6: Leg Press | B6: Inferior Members | C6: 4 | D6: 8 | E6: 3'
A7: Plank | B7: Core | C7: 4 | D7: 1×1' | E7: 3'
A8: Russian Sit-ups | B8: Core | C8: 4 | D8: 30 | E8: 3'
A9: Floor ABS Rotation | B9: Core | C9: 3 | D9: 20 | E9: 1'
A10: Leg + Arms Ups | B10: Core | C10: 3 | D10: 10 | E10: 3'
A11: Matrix Abd. N4 | B11: Core | C11: 4 | D11: 8 | E11: 3'
A12: Matrix Abd. Up | B12: Core | C12: 4 | D12: 10 | E12: 3'
A13: Rotary Torso | B13: Core | C13: 4 | D13: 8 | E13: 3'
... A51: Conv. Shoulder Press | B51: Superior – Machine | C51: 4 | D51: 8 | E51: 2'

Sheet 💪 Gym Session Log
A1: 💪 Gym Session Log
A2: ✏️ Enter: Date · Body Wt · Exercise (dropdown) · Intensity % · Weight Used — Sets, Reps, Rest & Max Ref fill automatically
A3: ✏️ = You fill in | G3: ⚡ = Auto-calculated
A4: Date | B4: Body Wt (kg) | C4: Category | D4: Exercise | E4: Intensity % | F4: Weight Used (kg) | G4: Sets | H4: Reps / Time | I4: Rest | J4: Max Ref (kg) | K4: Notes
A5: ── Session 1: 19 Sep 2024 · Body weight: 48.4 kg ──
A6: 45554 | B6: 48.4 | C6: =IFERROR(INDEX(Ref!$B$2:$B$43,MATCH(D6,Ref!$A$2:$A$43,0)),"") | D6: Hip Abductor | E6: 0.85 | F6: 32 | G6: =IFERROR(INDEX(Ref!$C$2:$C$43,MATCH(D6,Ref!$A$2:$A$43,0)),"") | H6: =IFERROR(INDEX(Ref!$D$2:$D$43,MATCH(D6,Ref!$A$2:$A$43,0)),"") | I6: =IFERROR(INDEX(Ref!$E$2:$E$43,MATCH(D6,Ref!$A$2:$A$43,0)),"") | J6: =IFERROR(IF(OR(E6="",F6="",ISNUMBER(FIND("bw",LOWER(TEXT(F6,"@"))))=TRUE()),"",ROUND(F6/E6,2)),"")
A7: 45554 | B7: 48.4 | C7: =IFERROR(INDEX(Ref!$B$2:$B$43,MATCH(D7,Ref!$A$2:$A$43,0)),"") | D7: Hip Adductor | E7: 0.85 | F7: 25 | G7: =IFERROR(INDEX(Ref!$C$2:$C$43,MATCH(D7,Ref!$A$2:$A$43,0)),"") | H7: =IFERROR(INDEX(Ref!$D$2:$D$43,MATCH(D7,Ref!$A$2:$A$43,0)),"") | I7: =IFERROR(INDEX(Ref!$E$2:$E$43,MATCH(D7,Ref!$A$2:$A$43,0)),"") | J7: =IFERROR(IF(OR(E7="",F7="",ISNUMBER(FIND("bw",LOWER(TEXT(F7,"@"))))=TRUE()),"",ROUND(F7/E7,2)),"")
A8: 45554 | B8: 48.4 | C8: =IFERROR(INDEX(Ref!$B$2:$B$43,MATCH(D8,Ref!$A$2:$A$43,0)),"") | D8: Ext. Quadriceps | E8: 0.85 | F8: 25 | G8: =IFERROR(INDEX(Ref!$C$2:$C$43,MATCH(D8,Ref!$A$2:$A$43,0)),"") | H8: =IFERROR(INDEX(Ref!$D$2:$D$43,MATCH(D8,Ref!$A$2:$A$43,0)),"") | I8: =IFERROR(INDEX(Ref!$E$2:$E$43,MATCH(D8,Ref!$A$2:$A$43,0)),"") | J8: =IFERROR(IF(OR(E8="",F8="",ISNUMBER(FIND("bw",LOWER(TEXT(F8,"@"))))=TRUE()),"",ROUND(F8/E8,2)),"")
A9: 45554 | B9: 48.4 | C9: =IFERROR(INDEX(Ref!$B$2:$B$43,MATCH(D9,Ref!$A$2:$A$43,0)),"") | D9: Plank | E9: 0.5 | F9: bw | G9: =IFERROR(INDEX(Ref!$C$2:$C$43,MATCH(D9,Ref!$A$2:$A$43,0)),"") | H9: =IFERROR(INDEX(Ref!$D$2:$D$43,MATCH(D9,Ref!$A$2:$A$43,0)),"") | I9: =IFERROR(INDEX(Ref!$E$2:$E$43,MATCH(D9,Ref!$A$2:$A$43,0)),"") | J9: =IFERROR(IF(OR(E9="",F9="",ISNUMBER(FIND("bw",LOWER(TEXT(F9,"@"))))=TRUE()),"",ROUND(F9/E9,2)),"")
A10: 45554 | B10: 48.4 | C10: =IFERROR(INDEX(Ref!$B$2:$B$43,MATCH(D10,Ref!$A$2:$A$43,0)),"") | D10: Russian Sit-ups | E10: 0.65 | F10: 6 | G10: =IFERROR(INDEX(Ref!$C$2:$C$43,MATCH(D10,Ref!$A$2:$A$43,0)),"") | H10: =IFERROR(INDEX(Ref!$D$2:$D$43,MATCH(D10,Ref!$A$2:$A$43,0)),"") | I10: =IFERROR(INDEX(Ref!$E$2:$E$43,MATCH(D10,Ref!$A$2:$A$43,0)),"") | J10: =IFERROR(IF(OR(E10="",F10="",ISNUMBER(FIND("bw",LOWER(TEXT(F10,"@"))))=TRUE()),"",ROUND(F10/E10,2)),"")
A11: 45554 | B11: 48.4 | C11: =IFERROR(INDEX(Ref!$B$2:$B$43,MATCH(D11,Ref!$A$2:$A$43,0)),"") | D11: Floor ABS Rotation | E11: 0.5 | F11: 2x2 | G11: =IFERROR(INDEX(Ref!$C$2:$C$43,MATCH(D11,Ref!$A$2:$A$43,0)),"") | H11: =IFERROR(INDEX(Ref!$D$2:$D$43,MATCH(D11,Ref!$A$2:$A$43,0)),"") | I11: =IFERROR(INDEX(Ref!$E$2:$E$43,MATCH(D11,Ref!$A$2:$A$43,0)),"") | J11: =IFERROR(IF(OR(E11="",F11="",ISNUMBER(FIND("bw",LOWER(TEXT(F11,"@"))))=TRUE()),"",ROUND(F11/E11,2)),"")
A12: 45554 | B12: 48.4 | C12: =IFERROR(INDEX(Ref!$B$2:$B$43,MATCH(D12,Ref!$A$2:$A$43,0)),"") | D12: Leg + Arms Ups | E12: 0.95 | F12: 12 | G12: =IFERROR(INDEX(Ref!$C$2:$C$43,MATCH(D12,Ref!$A$2:$A$43,0)),"") | H12: =IFERROR(INDEX(Ref!$D$2:$D$43,MATCH(D12,Ref!$A$2:$A$43,0)),"") | I12: =IFERROR(INDEX(Ref!$E$2:$E$43,MATCH(D12,Ref!$A$2:$A$43,0)),"") | J12: =IFERROR(IF(OR(E12="",F12="",ISNUMBER(FIND("bw",LOWER(TEXT(F12,"@"))))=TRUE()),"",ROUND(F12/E12,2)),"")
A13: 45554 | B13: 48.4 | C13: =IFERROR(INDEX(Ref!$B$2:$B$43,MATCH(D13,Ref!$A$2:$A$43,0)),"") | D13: Matrix Abd. N4 | E13: 0.85 | F13: 5 | G13: =IFERROR(INDEX(Ref!$C$2:$C$43,MATCH(D13,Ref!$A$2:$A$43,0)),"") | H13: =IFERROR(INDEX(Ref!$D$2:$D$43,MATCH(D13,Ref!$A$2:$A$43,0)),"") | I13: =IFERROR(INDEX(Ref!$E$2:$E$43,MATCH(D13,Ref!$A$2:$A$43,0)),"") | J13: =IFERROR(IF(OR(E13="",F13="",ISNUMBER(FIND("bw",LOWER(TEXT(F13,"@"))))=TRUE()),"",ROUND(F13/E13,2)),"")
A14: 45554 | B14: 48.4 | C14: =IFERROR(INDEX(Ref!$B$2:$B$43,MATCH(D14,Ref!$A$2:$A$43,0)),"") | D14: Matrix Back&Lat | F14: bw | G14: =IFERROR(INDEX(Ref!$C$2:$C$43,MATCH(D14,Ref!$A$2:$A$43,0)),"") | H14: =IFERROR(INDEX(Ref!$D$2:$D$43,MATCH(D14,Ref!$A$2:$A$43,0)),"") | I14: =IFERROR(INDEX(Ref!$E$2:$E$43,MATCH(D14,Ref!$A$2:$A$43,0)),"") | J14: =IFERROR(IF(OR(E14="",F14="",ISNUMBER(FIND("bw",LOWER(TEXT(F14,"@"))))=TRUE()),"",ROUND(F14/E14,2)),"")
A15: 45554 | B15: 48.4 | C15: =IFERROR(INDEX(Ref!$B$2:$B$43,MATCH(D15,Ref!$A$2:$A$43,0)),"") | D15: Scapular Pull-up | F15: bw | G15: =IFERROR(INDEX(Ref!$C$2:$C$43,MATCH(D15,Ref!$A$2:$A$43,0)),"") | H15: =IFERROR(INDEX(Ref!$D$2:$D$43,MATCH(D15,Ref!$A$2:$A$43,0)),"") | I15: =IFERROR(INDEX(Ref!$E$2:$E$43,MATCH(D15,Ref!$A$2:$A$43,0)),"") | J15: =IFERROR(IF(OR(E15="",F15="",ISNUMBER(FIND("bw",LOWER(TEXT(F15,"@"))))=TRUE()),"",ROUND(F15/E15,2)),"")
A16: 45554 | B16: 48.4 | C16: =IFERROR(INDEX(Ref!$B$2:$B$43,MATCH(D16,Ref!$A$2:$A$43,0)),"") | D16: ISO Scapular Pull | F16: bw | G16: =IFERROR(INDEX(Ref!$C$2:$C$43,MATCH(D16,Ref!$A$2:$A$43,0)),"") | H16: =IFERROR(INDEX(Ref!$D$2:$D$43,MATCH(D16,Ref!$A$2:$A$43,0)),"") | I16: =IFERROR(INDEX(Ref!$E$2:$E$43,MATCH(D16,Ref!$A$2:$A$43,0)),"") | J16: =IFERROR(IF(OR(E16="",F16="",ISNUMBER(FIND("bw",LOWER(TEXT(F16,"@"))))=TRUE()),"",ROUND(F16/E16,2)),"")
A17: 45554 | B17: 48.4 | C17: =IFERROR(INDEX(Ref!$B$2:$B$43,MATCH(D17,Ref!$A$2:$A$43,0)),"") | D17: 1-Arm Scap. Pull-up | F17: bw | G17: =IFERROR(INDEX(Ref!$C$2:$C$43,MATCH(D17,Ref!$A$2:$A$43,0)),"") | H17: =IFERROR(INDEX(Ref!$D$2:$D$43,MATCH(D17,Ref!$A$2:$A$43,0)),"") | I17: =IFERROR(INDEX(Ref!$E$2:$E$43,MATCH(D17,Ref!$A$2:$A$43,0)),"") | J17: =IFERROR(IF(OR(E17="",F17="",ISNUMBER(FIND("bw",LOWER(TEXT(F17,"@"))))=TRUE()),"",ROUND(F17/E17,2)),"")
A18: 45554 | B18: 48.4 | C18: =IFERROR(INDEX(Ref!$B$2:$B$43,MATCH(D18,Ref!$A$2:$A$43,0)),"") | D18: Pull-up | F18: bw | G18: =IFERROR(INDEX(Ref!$C$2:$C$43,MATCH(D18,Ref!$A$2:$A$43,0)),"") | H18: =IFERROR(INDEX(Ref!$D$2:$D$43,MATCH(D18,Ref!$A$2:$A$43,0)),"") | I18: =IFERROR(INDEX(Ref!$E$2:$E$43,MATCH(D18,Ref!$A$2:$A$43,0)),"") | J18: =IFERROR(IF(OR(E18="",F18="",ISNUMBER(FIND("bw",LOWER(TEXT(F18,"@"))))=TRUE()),"",ROUND(F18/E18,2)),"")
A19: 45554 | B19: 48.4 | C19: =IFERROR(INDEX(Ref!$B$2:$B$43,MATCH(D19,Ref!$A$2:$A$43,0)),"") | D19: Lat Pulldown / Pull-up Bar | E19: 0.86 | F19: 36 | G19: =IFERROR(INDEX(Ref!$C$2:$C$43,MATCH(D19,Ref!$A$2:$A$43,0)),"") | H19: =IFERROR(INDEX(Ref!$D$2:$D$43,MATCH(D19,Ref!$A$2:$A$43,0)),"") | I19: =IFERROR(INDEX(Ref!$E$2:$E$43,MATCH(D19,Ref!$A$2:$A$43,0)),"") | J19: =IFERROR(IF(OR(E19="",F19="",ISNUMBER(FIND("bw",LOWER(TEXT(F19,"@"))))=TRUE()),"",ROUND(F19/E19,2)),"")
A20: 45554 | B20: 48.4 | C20: =IFERROR(INDEX(Ref!$B$2:$B$43,MATCH(D20,Ref!$A$2:$A$43,0)),"") | D20: Rear Deltoid N1 | E20: 0.9 | F20: 25 | G20: =IFERROR(INDEX(Ref!$C$2:$C$43,MATCH(D20,Ref!$A$2:$A$43,0)),"") | H20: =IFERROR(INDEX(Ref!$D$2:$D$43,MATCH(D20,Ref!$A$2:$A$43,0)),"") | I20: =IFERROR(INDEX(Ref!$E$2:$E$43,MATCH(D20,Ref!$A$2:$A$43,0)),"") | J20: =IFERROR(IF(OR(E20="",F20="",ISNUMBER(FIND("bw",LOWER(TEXT(F20,"@"))))=TRUE()),"",ROUND(F20/E20,2)),"")
A21: 45554 | B21: 48.4 | C21: =IFERROR(INDEX(Ref!$B$2:$B$43,MATCH(D21,Ref!$A$2:$A$43,0)),"") | D21: Fly Deltoid N2 | E21: 0.85 | F21: 39 | G21: =IFERROR(INDEX(Ref!$C$2:$C$43,MATCH(D21,Ref!$A$2:$A$43,0)),"") | H21: =IFERROR(INDEX(Ref!$D$2:$D$43,MATCH(D21,Ref!$A$2:$A$43,0)),"") | I21: =IFERROR(INDEX(Ref!$E$2:$E$43,MATCH(D21,Ref!$A$2:$A$43,0)),"") | J21: =IFERROR(IF(OR(E21="",F21="",ISNUMBER(FIND("bw",LOWER(TEXT(F21,"@"))))=TRUE()),"",ROUND(F21/E21,2)),"")
A22: 45554 | B22: 48.4 | C22: =IFERROR(INDEX(Ref!$B$2:$B$43,MATCH(D22,Ref!$A$2:$A$43,0)),"") | D22: Shoulder Press | E22: 0.9 | F22: 10.4 | G22: =IFERROR(INDEX(Ref!$C$2:$C$43,MATCH(D22,Ref!$A$2:$A$43,0)),"") | H22: =IFERROR(INDEX(Ref!$D$2:$D$43,MATCH(D22,Ref!$A$2:$A$43,0)),"") | I22: =IFERROR(INDEX(Ref!$E$2:$E$43,MATCH(D22,Ref!$A$2:$A$43,0)),"") | J22: =IFERROR(IF(OR(E22="",F22="",ISNUMBER(FIND("bw",LOWER(TEXT(F22,"@"))))=TRUE()),"",ROUND(F22/E22,2)),"")
A23: 45554 | B23: 48.4 | C23: =IFERROR(INDEX(Ref!$B$2:$B$43,MATCH(D23,Ref!$A$2:$A$43,0)),"") | D23: Chest Press | E23: 0.9 | F23: 29.6 | G23: =IFERROR(INDEX(Ref!$C$2:$C$43,MATCH(D23,Ref!$A$2:$A$43,0)),"") | H23: =IFERROR(INDEX(Ref!$D$2:$D$43,MATCH(D23,Ref!$A$2:$A$43,0)),"") | I23: =IFERROR(INDEX(Ref!$E$2:$E$43,MATCH(D23,Ref!$A$2:$A$43,0)),"") | J23: =IFERROR(IF(OR(E23="",F23="",ISNUMBER(FIND("bw",LOWER(TEXT(F23,"@"))))=TRUE()),"",ROUND(F23/E23,2)),"")
A24: 45554 | B24: 48.4 | C24: =IFERROR(INDEX(Ref!$B$2:$B$43,MATCH(D24,Ref!$A$2:$A$43,0)),"") | D24: Cable Cross Over | E24: 0.9 | F24: 14 | G24: =IFERROR(INDEX(Ref!$C$2:$C$43,MATCH(D24,Ref!$A$2:$A$43,0)),"") | H24: =IFERROR(INDEX(Ref!$D$2:$D$43,MATCH(D24,Ref!$A$2:$A$43,0)),"") | I24: =IFERROR(INDEX(Ref!$E$2:$E$43,MATCH(D24,Ref!$A$2:$A$43,0)),"") | J24: =IFERROR(IF(OR(E24="",F24="",ISNUMBER(FIND("bw",LOWER(TEXT(F24,"@"))))=TRUE()),"",ROUND(F24/E24,2)),"")
A25: 45554 | B25: 48.4 | C25: =IFERROR(INDEX(Ref!$B$2:$B$43,MATCH(D25,Ref!$A$2:$A$43,0)),"") | D25: Low Row | E25: 0.8 | F25: 32 | G25: =IFERROR(INDEX(Ref!$C$2:$C$43,MATCH(D25,Ref!$A$2:$A$43,0)),"") | H25: =IFERROR(INDEX(Ref!$D$2:$D$43,MATCH(D25,Ref!$A$2:$A$43,0)),"") | I25: =IFERROR(INDEX(Ref!$E$2:$E$43,MATCH(D25,Ref!$A$2:$A$43,0)),"") | J25: =IFERROR(IF(OR(E25="",F25="",ISNUMBER(FIND("bw",LOWER(TEXT(F25,"@"))))=TRUE()),"",ROUND(F25/E25,2)),"")
A26: 45554 | B26: 48.4 | C26: =IFERROR(INDEX(Ref!$B$2:$B$43,MATCH(D26,Ref!$A$2:$A$43,0)),"") | D26: Shoulder Rotation | F26: 2 | G26: =IFERROR(INDEX(Ref!$C$2:$C$43,MATCH(D26,Ref!$A$2:$A$43,0)),"") | H26: =IFERROR(INDEX(Ref!$D$2:$D$43,MATCH(D26,Ref!$A$2:$A$43,0)),"") | I26: =IFERROR(INDEX(Ref!$E$2:$E$43,MATCH(D26,Ref!$A$2:$A$43,0)),"") | J26: =IFERROR(IF(OR(E26="",F26="",ISNUMBER(FIND("bw",LOWER(TEXT(F26,"@"))))=TRUE()),"",ROUND(F26/E26,2)),"")
A27: 45554 | B27: 48.4 | C27: =IFERROR(INDEX(Ref!$B$2:$B$43,MATCH(D27,Ref!$A$2:$A$43,0)),"") | D27: Biceps | E27: 0.85 | F27: 7 | G27: =IFERROR(INDEX(Ref!$C$2:$C$43,MATCH(D27,Ref!$A$2:$A$43,0)),"") | H27: =IFERROR(INDEX(Ref!$D$2:$D$43,MATCH(D27,Ref!$A$2:$A$43,0)),"") | I27: =IFERROR(INDEX(Ref!$E$2:$E$43,MATCH(D27,Ref!$A$2:$A$43,0)),"") | J27: =IFERROR(IF(OR(E27="",F27="",ISNUMBER(FIND("bw",LOWER(TEXT(F27,"@"))))=TRUE()),"",ROUND(F27/E27,2)),"")
A28: 45554 | B28: 48.4 | C28: =IFERROR(INDEX(Ref!$B$2:$B$43,MATCH(D28,Ref!$A$2:$A$43,0)),"") | D28: Wrist Extension | E28: 0.9 | F28: 4 | G28: =IFERROR(INDEX(Ref!$C$2:$C$43,MATCH(D28,Ref!$A$2:$A$43,0)),"") | H28: =IFERROR(INDEX(Ref!$D$2:$D$43,MATCH(D28,Ref!$A$2:$A$43,0)),"") | I28: =IFERROR(INDEX(Ref!$E$2:$E$43,MATCH(D28,Ref!$A$2:$A$43,0)),"") | J28: =IFERROR(IF(OR(E28="",F28="",ISNUMBER(FIND("bw",LOWER(TEXT(F28,"@"))))=TRUE()),"",ROUND(F28/E28,2)),"")
A29: 45554 | B29: 48.4 | C29: =IFERROR(INDEX(Ref!$B$2:$B$43,MATCH(D29,Ref!$A$2:$A$43,0)),"") | D29: Wrist Internal | E29: 0.8 | F29: 6 | G29: =IFERROR(INDEX(Ref!$C$2:$C$43,MATCH(D29,Ref!$A$2:$A$43,0)),"") | H29: =IFERROR(INDEX(Ref!$D$2:$D$43,MATCH(D29,Ref!$A$2:$A$43,0)),"") | I29: =IFERROR(INDEX(Ref!$E$2:$E$43,MATCH(D29,Ref!$A$2:$A$43,0)),"") | J29: =IFERROR(IF(OR(E29="",F29="",ISNUMBER(FIND("bw",LOWER(TEXT(F29,"@"))))=TRUE()),"",ROUND(F29/E29,2)),"")
A30: 45554 | B30: 48.4 | C30: =IFERROR(INDEX(Ref!$B$2:$B$43,MATCH(D30,Ref!$A$2:$A$43,0)),"") | D30: Wrist Curls Int Roll | E30: 1 | F30: 2.5 | G30: =IFERROR(INDEX(Ref!$C$2:$C$43,MATCH(D30,Ref!$A$2:$A$43,0)),"") | H30: =IFERROR(INDEX(Ref!$D$2:$D$43,MATCH(D30,Ref!$A$2:$A$43,0)),"") | I30: =IFERROR(INDEX(Ref!$E$2:$E$43,MATCH(D30,Ref!$A$2:$A$43,0)),"") | J30: =IFERROR(IF(OR(E30="",F30="",ISNUMBER(FIND("bw",LOWER(TEXT(F30,"@"))))=TRUE()),"",ROUND(F30/E30,2)),"")
A31: 45554 | B31: 48.4 | C31: =IFERROR(INDEX(Ref!$B$2:$B$43,MATCH(D31,Ref!$A$2:$A$43,0)),"") | D31: Wrist Curls Ext Roll | E31: 1 | F31: 2.5 | G31: =IFERROR(INDEX(Ref!$C$2:$C$43,MATCH(D31,Ref!$A$2:$A$43,0)),"") | H31: =IFERROR(INDEX(Ref!$D$2:$D$43,MATCH(D31,Ref!$A$2:$A$43,0)),"") | I31: =IFERROR(INDEX(Ref!$E$2:$E$43,MATCH(D31,Ref!$A$2:$A$43,0)),"") | J31: =IFERROR(IF(OR(E31="",F31="",ISNUMBER(FIND("bw",LOWER(TEXT(F31,"@"))))=TRUE()),"",ROUND(F31/E31,2)),"")
A32: 45554 | B32: 48.4 | C32: =IFERROR(INDEX(Ref!$B$2:$B$43,MATCH(D32,Ref!$A$2:$A$43,0)),"") | D32: Grips w/ Machine | E32: 1 | F32: 35 | G32: =IFERROR(INDEX(Ref!$C$2:$C$43,MATCH(D32,Ref!$A$2:$A$43,0)),"") | H32: =IFERROR(INDEX(Ref!$D$2:$D$43,MATCH(D32,Ref!$A$2:$A$43,0)),"") | I32: =IFERROR(INDEX(Ref!$E$2:$E$43,MATCH(D32,Ref!$A$2:$A$43,0)),"") | J32: =IFERROR(IF(OR(E32="",F32="",ISNUMBER(FIND("bw",LOWER(TEXT(F32,"@"))))=TRUE()),"",ROUND(F32/E32,2)),"")
A34: ── Session 2: 24 Sep 2024 · Body weight: 48.4 kg ──
A35: 45559 | B35: 48.4 | C35: =IFERROR(INDEX(Ref!$B$2:$B$43,MATCH(D35,Ref!$A$2:$A$43,0)),"") | D35: Hip Abductor | E35: 0.9 | F35: 39 | G35: =IFERROR(INDEX(Ref!$C$2:$C$43,MATCH(D35,Ref!$A$2:$A$43,0)),"") | H35: =IFERROR(INDEX(Ref!$D$2:$D$43,MATCH(D35,Ref!$A$2:$A$43,0)),"") | I35: =IFERROR(INDEX(Ref!$E$2:$E$43,MATCH(D35,Ref!$A$2:$A$43,0)),"") | J35: =IFERROR(IF(OR(E35="",F35="",ISNUMBER(FIND("bw",LOWER(TEXT(F35,"@"))))=TRUE()),"",ROUND(F35/E35,2)),"")
A36: 45559 | B36: 48.4 | C36: =IFERROR(INDEX(Ref!$B$2:$B$43,MATCH(D36,Ref!$A$2:$A$43,0)),"") | D36: Hip Adductor | E36: 0.95 | F36: 32 | G36: =IFERROR(INDEX(Ref!$C$2:$C$43,MATCH(D36,Ref!$A$2:$A$43,0)),"") | H36: =IFERROR(INDEX(Ref!$D$2:$D$43,MATCH(D36,Ref!$A$2:$A$43,0)),"") | I36: =IFERROR(INDEX(Ref!$E$2:$E$43,MATCH(D36,Ref!$A$2:$A$43,0)),"") | J36: =IFERROR(IF(OR(E36="",F36="",ISNUMBER(FIND("bw",LOWER(TEXT(F36,"@"))))=TRUE()),"",ROUND(F36/E36,2)),"")
A37: 45559 | B37: 48.4 | C37: =IFERROR(INDEX(Ref!$B$2:$B$43,MATCH(D37,Ref!$A$2:$A$43,0)),"") | D37: Ext. Quadriceps | E37: 0.9 | F37: 32 | G37: =IFERROR(INDEX(Ref!$C$2:$C$43,MATCH(D37,Ref!$A$2:$A$43,0)),"") | H37: =IFERROR(INDEX(Ref!$D$2:$D$43,MATCH(D37,Ref!$A$2:$A$43,0)),"") | I37: =IFERROR(INDEX(Ref!$E$2:$E$43,MATCH(D37,Ref!$A$2:$A$43,0)),"") | J37: =IFERROR(IF(OR(E37="",F37="",ISNUMBER(FIND("bw",LOWER(TEXT(F37,"@"))))=TRUE()),"",ROUND(F37/E37,2)),"")
A38: 45559 | B38: 48.4 | C38: =IFERROR(INDEX(Ref!$B$2:$B$43,MATCH(D38,Ref!$A$2:$A$43,0)),"") | D38: Plank | E38: 0.5 | F38: bw | G38: =IFERROR(INDEX(Ref!$C$2:$C$43,MATCH(D38,Ref!$A$2:$A$43,0)),"") | H38: =IFERROR(INDEX(Ref!$D$2:$D$43,MATCH(D38,Ref!$A$2:$A$43,0)),"") | I38: =IFERROR(INDEX(Ref!$E$2:$E$43,MATCH(D38,Ref!$A$2:$A$43,0)),"") | J38: =IFERROR(IF(OR(E38="",F38="",ISNUMBER(FIND("bw",LOWER(TEXT(F38,"@"))))=TRUE()),"",ROUND(F38/E38,2)),"")
A39: 45559 | B39: 48.4 | C39: =IFERROR(INDEX(Ref!$B$2:$B$43,MATCH(D39,Ref!$A$2:$A$43,0)),"") | D39: Russian Sit-ups | E39: 0.65 | F39: 6 | G39: =IFERROR(INDEX(Ref!$C$2:$C$43,MATCH(D39,Ref!$A$2:$A$43,0)),"") | H39: =IFERROR(INDEX(Ref!$D$2:$D$43,MATCH(D39,Ref!$A$2:$A$43,0)),"") | I39: =IFERROR(INDEX(Ref!$E$2:$E$43,MATCH(D39,Ref!$A$2:$A$43,0)),"") | J39: =IFERROR(IF(OR(E39="",F39="",ISNUMBER(FIND("bw",LOWER(TEXT(F39,"@"))))=TRUE()),"",ROUND(F39/E39,2)),"")
A40: 45559 | B40: 48.4 | C40: =IFERROR(INDEX(Ref!$B$2:$B$43,MATCH(D40,Ref!$A$2:$A$43,0)),"") | D40: Floor ABS Rotation | E40: 0.8 | F40: 2x3 | G40: =IFERROR(INDEX(Ref!$C$2:$C$43,MATCH(D40,Ref!$A$2:$A$43,0)),"") | H40: =IFERROR(INDEX(Ref!$D$2:$D$43,MATCH(D40,Ref!$A$2:$A$43,0)),"") | I40: =IFERROR(INDEX(Ref!$E$2:$E$43,MATCH(D40,Ref!$A$2:$A$43,0)),"") | J40: =IFERROR(IF(OR(E40="",F40="",ISNUMBER(FIND("bw",LOWER(TEXT(F40,"@"))))=TRUE()),"",ROUND(F40/E40,2)),"")
A41: 45559 | B41: 48.4 | C41: =IFERROR(INDEX(Ref!$B$2:$B$43,MATCH(D41,Ref!$A$2:$A$43,0)),"") | D41: Leg + Arms Ups | E41: 0.95 | F41: 12 | G41: =IFERROR(INDEX(Ref!$C$2:$C$43,MATCH(D41,Ref!$A$2:$A$43,0)),"") | H41: =IFERROR(INDEX(Ref!$D$2:$D$43,MATCH(D41,Ref!$A$2:$A$43,0)),"") | I41: =IFERROR(INDEX(Ref!$E$2:$E$43,MATCH(D41,Ref!$A$2:$A$43,0)),"") | J41: =IFERROR(IF(OR(E41="",F41="",ISNUMBER(FIND("bw",LOWER(TEXT(F41,"@"))))=TRUE()),"",ROUND(F41/E41,2)),"")
...

Sheet 📈 Exercise Progress
A1: 📈 Exercise Progress — weight used per session (kg)
A3: Category | B3: Exercise | C3: 19 Sep 2024 | D3: 24 Sep 2024 | E3: 12 Jan 2025 | F3: 7 Mar 2025 | G3: 20 Aug 2025 | H3: 1 Jan 2026 | I3: Trend | J3: Notes
A4: ── Inferior Members ──
A5: Inferior Members | B5: Hip Abductor | C5: 32 | D5: 39 | E5: 35.1 | F5: 35.1 | G5: 36.55 | H5: 39 | I5: ↑ 7.0 kg
A6: Inferior Members | B6: Hip Adductor | C6: 25 | D6: 32 | E6: 30.4 | F6: 30.4 | G6: 31.96 | H6: 31.95 | I6: ↑ 6.9 kg
A7: Inferior Members | B7: Ext. Quadriceps | C7: 25 | D7: 32 | E7: 24.57 | F7: 24.57 | G7: 27.29 | H7: – | I7: ↑ 2.3 kg
A8: Inferior Members | B8: Prone Leg Curl | C8: – | D8: – | E8: 12.6 | F8: 12.6 | G8: 18.02 | H8: 23.01 | I8: ↑ 10.4 kg
A9: Inferior Members | B9: Leg Press | C9: – | D9: – | E9: – | F9: – | G9: 33.15 | H9: 45 | I9: ↑ 11.9 kg
A10: ── Core ──
A11: Core | B11: Plank | C11: btw | D11: btw | E11: btw | F11: btw | G11: btw | H11: bw | I11: →
A12: Core | B12: Russian Sit-ups | C12: 6 | D12: 6 | E12: 6 | F12: 6 | G12: 6 | H12: 6 | I12: ↓ 0.0 kg
A13: Core | B13: Floor ABS Rotation | C13: 2x2kg | D13: 2x3kg | E13: 2x3kg | F13: 2x3kg | G13: 2x3kg | H13: 2x3 | I13: →
A14: Core | B14: Leg + Arms Ups | C14: 12 | D14: 12 | E14: 12 | F14: 12 | G14: 12 | H14: 12 | I14: ↓ 0.0 kg
A15: Core | B15: Matrix Abd. N4 | C15: 5 | D15: 4 | E15: 4 | F15: 4 | G15: 4 | H15: 4 | I15: ↓ 1.0 kg
A16: Core | B16: Matrix Abd. Up | C16: – | D16: 10 | E16: 10 | F16: 10 | G16: 10 | H16: 10 | I16: ↓ 0.0 kg
A17: Core | B17: Rotary Torso | C17: – | D17: – | E17: – | F17: – | G17: 23.04 | H17: 23.04 | I17: ↓ 0.0 kg
A18: ── Superior – No Machine ──
A19: Superior – No Machine | B19: Scapular Pull-up | C19: bw | D19: bw | E19: bw | F19: bw | G19: bw | H19: bw | I19: →
A20: Superior – No Machine | B20: ISO Scapular Pull | C20: bw | D20: bw | E20: bw | F20: bw | G20: bw | H20: bw | I20: →
A21: Superior – No Machine | B21: 1-Arm Scap. Pull-up | C21: bw | D21: bw | E21: bw | F21: bw | G21: bw | H21: bw | I21: →
A22: Superior – No Machine | B22: Pull-up | C22: bw | D22: bw | E22: bw | F22: bw | G22: bw | H22: bw | I22: →
A23: Superior – No Machine | B23: Pull-up + Weight | C23: – | D23: – | E23: – | F23: – | G23: +5kg | H23: +5kg | I23: →
A24: ── Superior – Machine ──
A25: Superior – Machine | B25: Lat Pulldown / Pull-up Bar | C25: 36 | D25: 41 | E25: 41 | F25: 41 | G25: 39.02 | H25: 39 | I25: ↑ 3.0 kg
A26: Superior – Machine | B26: Rear Deltoid N1 | C26: 25 | D26: 32 | E26: 32 | F26: 32 | G26: 24.99 | H26: 25.13 | I26: ↑ 0.1 kg
A27: Superior – Machine | B27: Fly Deltoid N2 | C27: 39 | D27: 39 | E27: 39 | F27: 39 | G27: 32.05 | H27: 39 | I27: ↓ 0.0 kg
A28: Superior – Machine | B28: Shoulder Press | C28: 10.4 | D28: 10.4 | E28: 10.4 | F28: 10.4 | G28: 18.02 | H28: 18 | I28: ↑ 7.6 kg
A29: Superior – Machine | B29: Chest Press | C29: 29.6 | D29: 29.6 | E29: 29.6 | F29: 29.6 | G29: 25.08 | H29: 27.3 | I29: ↓ 2.3 kg
A30: Superior – Machine | B30: Cable Cross Over | C30: 14 | D30: 14 | E30: 14 | F30: 14 | G30: 11.9 | H30: 10.5 | I30: ↓ 3.5 kg
A31: Superior – Machine | B31: Low Row | C31: 32 | D31: 32 | E31: 32 | F31: 32 | G31: 27.2 | H31: – | I31: ↓ 4.8 kg
A32: Superior – Machine | B32: Shoulder Rotation | C32: 2 | D32: 2 | E32: 2 | F32: 2 | G32: 1.7 | H32: 1.5 | I32: ↓ 0.5 kg
A33: Superior – Machine | B33: Biceps | C33: 7 | D33: 7 | E33: 7 | F33: 7 | G33: 8.08 | H33: 6 | I33: ↓ 1.0 kg
A34: Superior – Machine | B34: Seated Triceps Press | C34: – | D34: 26.3 | E34: 26.3 | F34: 26.3 | G34: 34.51 | H34: 38.25 | I34: ↑ 11.9 kg
A35: Superior – Machine | B35: Seated Row – Matrix | C35: – | D35: 26.3 | E35: – | F35: – | G35: – | H35: – | I35: →
A36: ── Wrist ──
A37: Wrist | B37: Wrist Extension | C37: 4 | D37: 4 | E37: 4 | F37: 4 | G37: 8.08 | H37: 8.03 | I37: ↑ 4.0 kg
A38: Wrist | B38: Wrist Internal | C38: 6 | D38: 6 | E38: 6 | F38: 6 | G38: 6.03 | H38: 4.01 | I38: ↓ 2.0 kg
A39: Wrist | B39: Wrist Curls Int Roll | C39: 2.5 | D39: 2.5 | E39: 2.5 | F39: 2.5 | G39: 6.03 | H39: 5.33 | I39: ↑ 2.8 kg
A40: Wrist | B40: Wrist Curls Ext Roll | C40: 2.5 | D40: 2.5 | E40: 2.5 | F40: 2.5 | G40: 4.25 | H40: 3.75 | I40: ↑ 1.2 kg
A41: ── Fingers ──
...

Sheet 🦵 Rehab Program
A1: 🦵 Rehab Programme — Calf / FisioHolland (Dyllan) | Surgery: 29 Aug 2025
A3: Phase / Week | B3: Exercise | C3: Sets | D3: Reps | E3: Tempo | F3: Rest (Set) | G3: Rest (Ex) | H3: Weight (kg) | I3: Intensity % | J3: Notes / Progress
A4: Week 1 (2–3×/week) · 2 Jul – 7 Jul 2025
B5: Leg Press (Calfs) | C5: 3 | D5: 15 | E5: 8''–10'' | F5: 1'–2' | G5: 3'–5' | H5: 40 | I5: 60%
B6: Calfs Raise (w/ weight) | C6: 3 | D6: 15 | E6: 8''–10'' | F6: 1'–2' | G6: 3'–5' | H6: bw | I6: 60%
B7: Leg Curl (Machine) | C7: 3 | D7: 15 | E7: 8''–10'' | F7: 1'–2' | G7: 3'–5' | H7: 25 | I7: 60%
A8: Session dates done: | B8: 1: | D8: 2: | F8: 3: | H8: RPE:
A10: Weeks 2–3 (2–3×/week) · 13 Jul – 27 Jul 2025
B11: Leg Press (Calfs) | C11: 3 | D11: 12 | E11: 8''–10'' | F11: 1'–2' | G11: 3'–5' | H11: 42.3 | I11: 65%
B12: Calfs Raise (w/ weight) | C12: 3 | D12: 12 | E12: 8''–10'' | F12: 1'–2' | G12: 3'–5' | H12: bw | I12: 65%
B13: Leg Curl (Machine) | C13: 3 | D13: 12 | E13: 8''–10'' | F13: 1'–2' | G13: 3'–5' | H13: 27.3 | I13: 65%
A14: Session dates done: | B14: 1: | D14: 2: | F14: 3: | H14: RPE:
A16: Weeks 4–5 (2–3×/week) · 31 Jul – 8 Aug 2025 ⚠️ In Portugal
B17: Leg Press (Calfs) | C17: 4 | D17: 10 | E17: 8''–10'' | F17: 1'–2' | G17: 3'–5' | H17: 40 | I17: 70%
B18: Calfs Raise (w/ weight) | C18: 4 | D18: 10 | E18: 8''–10'' | F18: 1'–2' | G18: 3'–5' | H18: bw | I18: 70%
B19: Leg Curl (Machine) | C19: 4 | D19: 10 | E19: 8''–10'' | F19: 1'–2' | G19: 3'–5' | H19: 25 | I19: 70%
A20: Session dates done: | B20: 1: | D20: 2: | F20: 3: | H20: RPE:
A22: Weeks 6–8 (2–3×/week) · 12 Sep – 30 Sep 2025 ⚠️ Surgery 29 Aug — Restarted
B23: Leg Press (Calfs) | C23: 4 | D23: 8 | E23: 8''–10'' | F23: 1'–2' | G23: 3'–5' | H23: 45 | I23: 75%
B24: Calfs Raise (w/ weight) | C24: 4 | D24: 8 | E24: 8''–10'' | F24: 1'–2' | G24: 3'–5' | H24: 6 | I24: 75%
B25: Leg Curl (Machine) | C25: 4 | D25: 8 | E25: 8''–10'' | F25: 1'–2' | G25: 3'–5' | H25: 39 | I25: 75%
A26: Session dates done: | B26: 1: | D26: 2: | F26: 3: | H26: RPE:
A28: Weeks 9–12 (2–3×/week) · TBD — fill in dates below
B29: Leg Press (Calfs) | C29: 4 | D29: 6 | E29: 8''–10'' | F29: 1'–2' | G29: 3'–5' | H29: 45 | I29: 85%
B30: Calfs Raise (w/ weight) | C30: 4 | D30: 6 | E30: 8''–10'' | F30: 1'–2' | G30: 3'–5' | H30: 6 | I30: 85%
B31: Leg Curl (Machine) | C31: 4 | D31: 6 | E31: 8''–10'' | F31: 1'–2' | G31: 3'–5' | H31: 39 | I31: 85%
A32: Session dates done: | B32: 1: | D32: 2: | F32: 3: | H32: RPE:
A35: CURRENT GYM PROGRAMME (FH_25 Rehab) — Template from latest Lattice assessment
A36: ── Inferior Members ──
A37: Inferior Members | B37: Hip Abductor N.1 | C37: 4 | D37: 6 | G37: 3' | H37: 36.55 | I37: 85%
A38: Inferior Members | B38: Hip Adductor N.2 | C38: 4 | D38: 6 | G38: 3' | H38: 31.96 | I38: 85%
A39: Inferior Members | B39: Ext. Quadriceps | C39: 4 | D39: 6 | G39: 3' | H39: 27.29 | I39: 85%
A40: Inferior Members | B40: Prone Leg Curl (P7/P1-2) | C40: 3 | D40: 8 | G40: 3' | H40: 18.02 | I40: 85%
A41: Inferior Members | B41: Leg Press | C41: 4 | D41: 8 | G41: 3' | H41: 33.15 | I41: 85%
A42: ── Core ──
A43: Core | B43: Plank | C43: 4 | D43: 1 | G43: 3' | H43: btw | I43: 50%
A44: Core | B44: Russian Sit-ups | C44: 4 | D44: 30 | G44: 3' | H44: 6 | I44: 65%
A45: Core | B45: Floor ABS Rotation | C45: 3 | D45: 20 | G45: 1' | H45: 2x3kg | I45: 80%
A46: Core | B46: Leg + Arms Ups | C46: 3 | D46: 10 | G46: 3' | H46: 12 | I46: 95%
A47: Core | B47: Matrix Abd. N4 | C47: 4 | D47: 8 | G47: 3' | H47: 4 | I47: 85%
...

Sheet 🧗 Climbing Log
A1: 🧗 Climbing Log — meters auto-calculated from gym wall height
A2: ✏️ Fill: Date · Gym (dropdown) · Duration · Route counts per grade | ⚡ Auto: Wall Height · Total Routes · Total Meters · Meters per Grade
P3: ⬇ Meters per Grade Band (auto)
A4: Date | B4: Gym | C4: Wall Ht (m) | D4: Duration (min) | E4: 3–4c | F4: 5a–5b+ | G4: 5c–5c+ | H4: 6a–6a+ | I4: 6b–6b+ | J4: 6c–6c+ | K4: 7a–7a+ | L4: 7b–7b+ | M4: Total Routes | N4: Total Meters | O4: Notes | P4: m @ 3–4c | Q4: m @ 5a–5b+ | R4: m @ 5c–5c+ | S4: m @ 6a–6a+ | T4: m @ 6b–6b+ | U4: m @ 6c–6c+ | V4: m @ 7a–7a+ | W4: m @ 7b–7b+
A5: 45609 | B5: Neoliet | C5: =IFERROR(INDEX('🧗 Climbing Log'!$B$75:$B$80,MATCH(B5,'🧗 Climbing Log'!$A$75:$A$80,0)),"") | D5: 90 | F5: 6 | G5: 8 | M5: =IFERROR(SUM(E5:L5),0) | N5: =IFERROR(IF(OR(C5="",M5=0),"",M5*C5),"") | O5: Week 46 – session 1 | P5: =IFERROR(IF(OR(C5="",E5=0),"",E5*C5),"") | Q5: =IFERROR(IF(OR(C5="",F5=0),"",F5*C5),"") | R5: =IFERROR(IF(OR(C5="",G5=0),"",G5*C5),"") | S5: =IFERROR(IF(OR(C5="",H5=0),"",H5*C5),"") | T5: =IFERROR(IF(OR(C5="",I5=0),"",I5*C5),"") | U5: =IFERROR(IF(OR(C5="",J5=0),"",J5*C5),"") | V5: =IFERROR(IF(OR(C5="",K5=0),"",K5*C5),"") | W5: =IFERROR(IF(OR(C5="",L5=0),"",L5*C5),"")
A6: 45616 | B6: Neoliet | C6: =IFERROR(INDEX('🧗 Climbing Log'!$B$75:$B$80,MATCH(B6,'🧗 Climbing Log'!$A$75:$A$80,0)),"") | D6: 90 | F6: 10 | H6: 2 | M6: =IFERROR(SUM(E6:L6),0) | N6: =IFERROR(IF(OR(C6="",M6=0),"",M6*C6),"") | O6: Week 46 – session 2 | P6: =IFERROR(IF(OR(C6="",E6=0),"",E6*C6),"") | Q6: =IFERROR(IF(OR(C6="",F6=0),"",F6*C6),"") | R6: =IFERROR(IF(OR(C6="",G6=0),"",G6*C6),"") | S6: =IFERROR(IF(OR(C6="",H6=0),"",H6*C6),"") | T6: =IFERROR(IF(OR(C6="",I6=0),"",I6*C6),"") | U6: =IFERROR(IF(OR(C6="",J6=0),"",J6*C6),"") | V6: =IFERROR(IF(OR(C6="",K6=0),"",K6*C6),"") | W6: =IFERROR(IF(OR(C6="",L6=0),"",L6*C6),"")
A7: 45623 | B7: Neoliet | C7: =IFERROR(INDEX('🧗 Climbing Log'!$B$75:$B$80,MATCH(B7,'🧗 Climbing Log'!$A$75:$A$80,0)),"") | D7: 90 | F7: 10 | G7: 7 | H7: 2 | M7: =IFERROR(SUM(E7:L7),0) | N7: =IFERROR(IF(OR(C7="",M7=0),"",M7*C7),"") | O7: Week 47 | P7: =IFERROR(IF(OR(C7="",E7=0),"",E7*C7),"") | Q7: =IFERROR(IF(OR(C7="",F7=0),"",F7*C7),"") | R7: =IFERROR(IF(OR(C7="",G7=0),"",G7*C7),"") | S7: =IFERROR(IF(OR(C7="",H7=0),"",H7*C7),"") | T7: =IFERROR(IF(OR(C7="",I7=0),"",I7*C7),"") | U7: =IFERROR(IF(OR(C7="",J7=0),"",J7*C7),"") | V7: =IFERROR(IF(OR(C7="",K7=0),"",K7*C7),"") | W7: =IFERROR(IF(OR(C7="",L7=0),"",L7*C7),"")
A8: 45630 | B8: Neoliet | C8: =IFERROR(INDEX('🧗 Climbing Log'!$B$75:$B$80,MATCH(B8,'🧗 Climbing Log'!$A$75:$A$80,0)),"") | D8: 90 | F8: 10 | G8: 7 | H8: 2 | M8: =IFERROR(SUM(E8:L8),0) | N8: =IFERROR(IF(OR(C8="",M8=0),"",M8*C8),"") | O8: Week 48 | P8: =IFERROR(IF(OR(C8="",E8=0),"",E8*C8),"") | Q8: =IFERROR(IF(OR(C8="",F8=0),"",F8*C8),"") | R8: =IFERROR(IF(OR(C8="",G8=0),"",G8*C8),"") | S8: =IFERROR(IF(OR(C8="",H8=0),"",H8*C8),"") | T8: =IFERROR(IF(OR(C8="",I8=0),"",I8*C8),"") | U8: =IFERROR(IF(OR(C8="",J8=0),"",J8*C8),"") | V8: =IFERROR(IF(OR(C8="",K8=0),"",K8*C8),"") | W8: =IFERROR(IF(OR(C8="",L8=0),"",L8*C8),"")
A9: 45665 | B9: Neoliet | C9: =IFERROR(INDEX('🧗 Climbing Log'!$B$75:$B$80,MATCH(B9,'🧗 Climbing Log'!$A$75:$A$80,0)),"") | D9: 90 | M9: =IFERROR(SUM(E9:L9),0) | N9: =IFERROR(IF(OR(C9="",M9=0),"",M9*C9),"") | O9: OS 6a+/6b (Lattice ref) | P9: =IFERROR(IF(OR(C9="",E9=0),"",E9*C9),"") | Q9: =IFERROR(IF(OR(C9="",F9=0),"",F9*C9),"") | R9: =IFERROR(IF(OR(C9="",G9=0),"",G9*C9),"") | S9: =IFERROR(IF(OR(C9="",H9=0),"",H9*C9),"") | T9: =IFERROR(IF(OR(C9="",I9=0),"",I9*C9),"") | U9: =IFERROR(IF(OR(C9="",J9=0),"",J9*C9),"") | V9: =IFERROR(IF(OR(C9="",K9=0),"",K9*C9),"") | W9: =IFERROR(IF(OR(C9="",L9=0),"",L9*C9),"")
A10: 45889 | B10: Neoliet | C10: =IFERROR(INDEX('🧗 Climbing Log'!$B$75:$B$80,MATCH(B10,'🧗 Climbing Log'!$A$75:$A$80,0)),"") | D10: 90 | M10: =IFERROR(SUM(E10:L10),0) | N10: =IFERROR(IF(OR(C10="",M10=0),"",M10*C10),"") | P10: =IFERROR(IF(OR(C10="",E10=0),"",E10*C10),"") | Q10: =IFERROR(IF(OR(C10="",F10=0),"",F10*C10),"") | R10: =IFERROR(IF(OR(C10="",G10=0),"",G10*C10),"") | S10: =IFERROR(IF(OR(C10="",H10=0),"",H10*C10),"") | T10: =IFERROR(IF(OR(C10="",I10=0),"",I10*C10),"") | U10: =IFERROR(IF(OR(C10="",J10=0),"",J10*C10),"") | V10: =IFERROR(IF(OR(C10="",K10=0),"",K10*C10),"") | W10: =IFERROR(IF(OR(C10="",L10=0),"",L10*C10),"")
A12: ── January–February 2026 · Sport OS: 6c+ · RP target: 7a ──
A13: 46030 | B13: Neoliet (Outdoor) | C13: =IFERROR(INDEX('🧗 Climbing Log'!$B$75:$B$80,MATCH(B13,'🧗 Climbing Log'!$A$75:$A$80,0)),"") | D13: 120 | E13: 2 | F13: 4 | G13: 3 | H13: 5 | M13: =IFERROR(SUM(E13:L13),0) | N13: =IFERROR(IF(OR(C13="",M13=0),"",M13*C13),"") | O13: Wk1 – Neoliet Outdoor, 20m, base building | P13: =IFERROR(IF(OR(C13="",E13=0),"",E13*C13),"") | Q13: =IFERROR(IF(OR(C13="",F13=0),"",F13*C13),"") | R13: =IFERROR(IF(OR(C13="",G13=0),"",G13*C13),"") | S13: =IFERROR(IF(OR(C13="",H13=0),"",H13*C13),"") | T13: =IFERROR(IF(OR(C13="",I13=0),"",I13*C13),"") | U13: =IFERROR(IF(OR(C13="",J13=0),"",J13*C13),"") | V13: =IFERROR(IF(OR(C13="",K13=0),"",K13*C13),"") | W13: =IFERROR(IF(OR(C13="",L13=0),"",L13*C13),"")
A14: 46035 | B14: Sterk | C14: =IFERROR(INDEX('🧗 Climbing Log'!$B$75:$B$80,MATCH(B14,'🧗 Climbing Log'!$A$75:$A$80,0)),"") | D14: 120 | E14: 2 | F14: 2 | G14: 2 | H14: 2 | M14: =IFERROR(SUM(E14:L14),0) | N14: =IFERROR(IF(OR(C14="",M14=0),"",M14*C14),"") | O14: Wk2 S1 – Sterk bouldering | P14: =IFERROR(IF(OR(C14="",E14=0),"",E14*C14),"") | Q14: =IFERROR(IF(OR(C14="",F14=0),"",F14*C14),"") | R14: =IFERROR(IF(OR(C14="",G14=0),"",G14*C14),"") | S14: =IFERROR(IF(OR(C14="",H14=0),"",H14*C14),"") | T14: =IFERROR(IF(OR(C14="",I14=0),"",I14*C14),"") | U14: =IFERROR(IF(OR(C14="",J14=0),"",J14*C14),"") | V14: =IFERROR(IF(OR(C14="",K14=0),"",K14*C14),"") | W14: =IFERROR(IF(OR(C14="",L14=0),"",L14*C14),"")
A15: 46038 | B15: Sterk | C15: =IFERROR(INDEX('🧗 Climbing Log'!$B$75:$B$80,MATCH(B15,'🧗 Climbing Log'!$A$75:$A$80,0)),"") | D15: 105 | E15: 4 | F15: 5 | G15: 4 | H15: 1 | M15: =IFERROR(SUM(E15:L15),0) | N15: =IFERROR(IF(OR(C15="",M15=0),"",M15*C15),"") | O15: Wk2 S2 – Sterk bouldering | P15: =IFERROR(IF(OR(C15="",E15=0),"",E15*C15),"") | Q15: =IFERROR(IF(OR(C15="",F15=0),"",F15*C15),"") | R15: =IFERROR(IF(OR(C15="",G15=0),"",G15*C15),"") | S15: =IFERROR(IF(OR(C15="",H15=0),"",H15*C15),"") | T15: =IFERROR(IF(OR(C15="",I15=0),"",I15*C15),"") | U15: =IFERROR(IF(OR(C15="",J15=0),"",J15*C15),"") | V15: =IFERROR(IF(OR(C15="",K15=0),"",K15*C15),"") | W15: =IFERROR(IF(OR(C15="",L15=0),"",L15*C15),"")
A16: 46042 | B16: Neoliet | C16: =IFERROR(INDEX('🧗 Climbing Log'!$B$75:$B$80,MATCH(B16,'🧗 Climbing Log'!$A$75:$A$80,0)),"") | D16: 105 | E16: 2 | F16: 3 | G16: 6 | H16: 6 | M16: =IFERROR(SUM(E16:L16),0) | N16: =IFERROR(IF(OR(C16="",M16=0),"",M16*C16),"") | O16: Wk3 S1 – Neoliet 13m | P16: =IFERROR(IF(OR(C16="",E16=0),"",E16*C16),"") | Q16: =IFERROR(IF(OR(C16="",F16=0),"",F16*C16),"") | R16: =IFERROR(IF(OR(C16="",G16=0),"",G16*C16),"") | S16: =IFERROR(IF(OR(C16="",H16=0),"",H16*C16),"") | T16: =IFERROR(IF(OR(C16="",I16=0),"",I16*C16),"") | U16: =IFERROR(IF(OR(C16="",J16=0),"",J16*C16),"") | V16: =IFERROR(IF(OR(C16="",K16=0),"",K16*C16),"") | W16: =IFERROR(IF(OR(C16="",L16=0),"",L16*C16),"")
A17: 46044 | B17: Neoliet | C17: =IFERROR(INDEX('🧗 Climbing Log'!$B$75:$B$80,MATCH(B17,'🧗 Climbing Log'!$A$75:$A$80,0)),"") | D17: 150 | E17: 3 | F17: 3 | G17: 2 | H17: 11 | I17: 1 | M17: =IFERROR(SUM(E17:L17),0) | N17: =IFERROR(IF(OR(C17="",M17=0),"",M17*C17),"") | O17: Wk3 S2 – Neoliet 13m, pushing 6b | P17: =IFERROR(IF(OR(C17="",E17=0),"",E17*C17),"") | Q17: =IFERROR(IF(OR(C17="",F17=0),"",F17*C17),"") | R17: =IFERROR(IF(OR(C17="",G17=0),"",G17*C17),"") | S17: =IFERROR(IF(OR(C17="",H17=0),"",H17*C17),"") | T17: =IFERROR(IF(OR(C17="",I17=0),"",I17*C17),"") | U17: =IFERROR(IF(OR(C17="",J17=0),"",J17*C17),"") | V17: =IFERROR(IF(OR(C17="",K17=0),"",K17*C17),"") | W17: =IFERROR(IF(OR(C17="",L17=0),"",L17*C17),"")
A18: 46046 | B18: Sterk | C18: =IFERROR(INDEX('🧗 Climbing Log'!$B$75:$B$80,MATCH(B18,'🧗 Climbing Log'!$A$75:$A$80,0)),"") | D18: 60 | E18: 6 | F18: 6 | G18: 6 | H18: 2 | M18: =IFERROR(SUM(E18:L18),0) | N18: =IFERROR(IF(OR(C18="",M18=0),"",M18*C18),"") | O18: Wk3 S3 – Sterk bouldering | P18: =IFERROR(IF(OR(C18="",E18=0),"",E18*C18),"") | Q18: =IFERROR(IF(OR(C18="",F18=0),"",F18*C18),"") | R18: =IFERROR(IF(OR(C18="",G18=0),"",G18*C18),"") | S18: =IFERROR(IF(OR(C18="",H18=0),"",H18*C18),"") | T18: =IFERROR(IF(OR(C18="",I18=0),"",I18*C18),"") | U18: =IFERROR(IF(OR(C18="",J18=0),"",J18*C18),"") | V18: =IFERROR(IF(OR(C18="",K18=0),"",K18*C18),"") | W18: =IFERROR(IF(OR(C18="",L18=0),"",L18*C18),"")
A19: 46049 | B19: Neoliet | C19: =IFERROR(INDEX('🧗 Climbing Log'!$B$75:$B$80,MATCH(B19,'🧗 Climbing Log'!$A$75:$A$80,0)),"") | D19: 120 | E19: 2 | F19: 4 | G19: 5 | H19: 5 | I19: 4 | M19: =IFERROR(SUM(E19:L19),0) | N19: =IFERROR(IF(OR(C19="",M19=0),"",M19*C19),"") | O19: Wk4 – Neoliet 13m | P19: =IFERROR(IF(OR(C19="",E19=0),"",E19*C19),"") | Q19: =IFERROR(IF(OR(C19="",F19=0),"",F19*C19),"") | R19: =IFERROR(IF(OR(C19="",G19=0),"",G19*C19),"") | S19: =IFERROR(IF(OR(C19="",H19=0),"",H19*C19),"") | T19: =IFERROR(IF(OR(C19="",I19=0),"",I19*C19),"") | U19: =IFERROR(IF(OR(C19="",J19=0),"",J19*C19),"") | V19: =IFERROR(IF(OR(C19="",K19=0),"",K19*C19),"") | W19: =IFERROR(IF(OR(C19="",L19=0),"",L19*C19),"")
A20: ↓ LOG YOUR NEXT SESSION HERE — select gym from dropdown, fill yellow cells ↓
C21: =IFERROR(INDEX('🧗 Climbing Log'!$B$75:$B$80,MATCH(B13,'🧗 Climbing Log'!$A$75:$A$80,0)),"") | M21: =IFERROR(SUM(E13:L13),0) | N21: =IFERROR(IF(OR(C13="",M13=0),"",M13*C13),"") | P21: =IFERROR(IF(OR(C13="",E13=0),"",E13*C13),"") | Q21: =IFERROR(IF(OR(C13="",F13=0),"",F13*C13),"") | R21: =IFERROR(IF(OR(C13="",G13=0),"",G13*C13),"") | S21: =IFERROR(IF(OR(C13="",H13=0),"",H13*C13),"") | T21: =IFERROR(IF(OR(C13="",I13=0),"",I13*C13),"") | U21: =IFERROR(IF(OR(C13="",J13=0),"",J13*C13),"") | V21: =IFERROR(IF(OR(C13="",K13=0),"",K13*C13),"") | W21: =IFERROR(IF(OR(C13="",L13=0),"",L13*C13),"")
C22: =IFERROR(INDEX('🧗 Climbing Log'!$B$75:$B$80,MATCH(B14,'🧗 Climbing Log'!$A$75:$A$80,0)),"") | M22: =IFERROR(SUM(E14:L14),0) | N22: =IFERROR(IF(OR(C14="",M14=0),"",M14*C14),"") | P22: =IFERROR(IF(OR(C14="",E14=0),"",E14*C14),"") | Q22: =IFERROR(IF(OR(C14="",F14=0),"",F14*C14),"") | R22: =IFERROR(IF(OR(C14="",G14=0),"",G14*C14),"") | S22: =IFERROR(IF(OR(C14="",H14=0),"",H14*C14),"") | T22: =IFERROR(IF(OR(C14="",I14=0),"",I14*C14),"") | U22: =IFERROR(IF(OR(C14="",J14=0),"",J14*C14),"") | V22: =IFERROR(IF(OR(C14="",K14=0),"",K14*C14),"") | W22: =IFERROR(IF(OR(C14="",L14=0),"",L14*C14),"")
C23: =IFERROR(INDEX('🧗 Climbing Log'!$B$75:$B$80,MATCH(B15,'🧗 Climbing Log'!$A$75:$A$80,0)),"") | M23: =IFERROR(SUM(E15:L15),0) | N23: =IFERROR(IF(OR(C15="",M15=0),"",M15*C15),"") | P23: =IFERROR(IF(OR(C15="",E15=0),"",E15*C15),"") | Q23: =IFERROR(IF(OR(C15="",F15=0),"",F15*C15),"") | R23: =IFERROR(IF(OR(C15="",G15=0),"",G15*C15),"") | S23: =IFERROR(IF(OR(C15="",H15=0),"",H15*C15),"") | T23: =IFERROR(IF(OR(C15="",I15=0),"",I15*C15),"") | U23: =IFERROR(IF(OR(C15="",J15=0),"",J15*C15),"") | V23: =IFERROR(IF(OR(C15="",K15=0),"",K15*C15),"") | W23: =IFERROR(IF(OR(C15="",L15=0),"",L15*C15),"")
C24: =IFERROR(INDEX('🧗 Climbing Log'!$B$75:$B$80,MATCH(B16,'🧗 Climbing Log'!$A$75:$A$80,0)),"") | M24: =IFERROR(SUM(E16:L16),0) | N24: =IFERROR(IF(OR(C16="",M16=0),"",M16*C16),"") | P24: =IFERROR(IF(OR(C16="",E16=0),"",E16*C16),"") | Q24: =IFERROR(IF(OR(C16="",F16=0),"",F16*C16),"") | R24: =IFERROR(IF(OR(C16="",G16=0),"",G16*C16),"") | S24: =IFERROR(IF(OR(C16="",H16=0),"",H16*C16),"") | T24: =IFERROR(IF(OR(C16="",I16=0),"",I16*C16),"") | U24: =IFERROR(IF(OR(C16="",J16=0),"",J16*C16),"") | V24: =IFERROR(IF(OR(C16="",K16=0),"",K16*C16),"") | W24: =IFERROR(IF(OR(C16="",L16=0),"",L16*C16),"")
C25: =IFERROR(INDEX('🧗 Climbing Log'!$B$75:$B$80,MATCH(B17,'🧗 Climbing Log'!$A$75:$A$80,0)),"") | M25: =IFERROR(SUM(E17:L17),0) | N25: =IFERROR(IF(OR(C17="",M17=0),"",M17*C17),"") | P25: =IFERROR(IF(OR(C17="",E17=0),"",E17*C17),"") | Q25: =IFERROR(IF(OR(C17="",F17=0),"",F17*C17),"") | R25: =IFERROR(IF(OR(C17="",G17=0),"",G17*C17),"") | S25: =IFERROR(IF(OR(C17="",H17=0),"",H17*C17),"") | T25: =IFERROR(IF(OR(C17="",I17=0),"",I17*C17),"") | U25: =IFERROR(IF(OR(C17="",J17=0),"",J17*C17),"") | V25: =IFERROR(IF(OR(C17="",K17=0),"",K17*C17),"") | W25: =IFERROR(IF(OR(C17="",L17=0),"",L17*C17),"")
C26: =IFERROR(INDEX('🧗 Climbing Log'!$B$75:$B$80,MATCH(B18,'🧗 Climbing Log'!$A$75:$A$80,0)),"") | M26: =IFERROR(SUM(E18:L18),0) | N26: =IFERROR(IF(OR(C18="",M18=0),"",M18*C18),"") | P26: =IFERROR(IF(OR(C18="",E18=0),"",E18*C18),"") | Q26: =IFERROR(IF(OR(C18="",F18=0),"",F18*C18),"") | R26: =IFERROR(IF(OR(C18="",G18=0),"",G18*C18),"") | S26: =IFERROR(IF(OR(C18="",H18=0),"",H18*C18),"") | T26: =IFERROR(IF(OR(C18="",I18=0),"",I18*C18),"") | U26: =IFERROR(IF(OR(C18="",J18=0),"",J18*C18),"") | V26: =IFERROR(IF(OR(C18="",K18=0),"",K18*C18),"") | W26: =IFERROR(IF(OR(C18="",L18=0),"",L18*C18),"")
C27: =IFERROR(INDEX('🧗 Climbing Log'!$B$75:$B$80,MATCH(B19,'🧗 Climbing Log'!$A$75:$A$80,0)),"") | M27: =IFERROR(SUM(E19:L19),0) | N27: =IFERROR(IF(OR(C19="",M19=0),"",M19*C19),"") | P27: =IFERROR(IF(OR(C19="",E19=0),"",E19*C19),"") | Q27: =IFERROR(IF(OR(C19="",F19=0),"",F19*C19),"") | R27: =IFERROR(IF(OR(C19="",G19=0),"",G19*C19),"") | S27: =IFERROR(IF(OR(C19="",H19=0),"",H19*C19),"") | T27: =IFERROR(IF(OR(C19="",I19=0),"",I19*C19),"") | U27: =IFERROR(IF(OR(C19="",J19=0),"",J19*C19),"") | V27: =IFERROR(IF(OR(C19="",K19=0),"",K19*C19),"") | W27: =IFERROR(IF(OR(C19="",L19=0),"",L19*C19),"")
C28: =IFERROR(INDEX('🧗 Climbing Log'!$B$75:$B$80,MATCH(B20,'🧗 Climbing Log'!$A$75:$A$80,0)),"") | M28: =IFERROR(SUM(E20:L20),0) | N28: =IFERROR(IF(OR(C20="",M20=0),"",M20*C20),"") | P28: =IFERROR(IF(OR(C20="",E20=0),"",E20*C20),"") | Q28: =IFERROR(IF(OR(C20="",F20=0),"",F20*C20),"") | R28: =IFERROR(IF(OR(C20="",G20=0),"",G20*C20),"") | S28: =IFERROR(IF(OR(C20="",H20=0),"",H20*C20),"") | T28: =IFERROR(IF(OR(C20="",I20=0),"",I20*C20),"") | U28: =IFERROR(IF(OR(C20="",J20=0),"",J20*C20),"") | V28: =IFERROR(IF(OR(C20="",K20=0),"",K20*C20),"") | W28: =IFERROR(IF(OR(C20="",L20=0),"",L20*C20),"")
C29: =IFERROR(INDEX('🧗 Climbing Log'!$B$75:$B$80,MATCH(B21,'🧗 Climbing Log'!$A$75:$A$80,0)),"") | M29: =IFERROR(SUM(E21:L21),0) | N29: =IFERROR(IF(OR(C21="",M21=0),"",M21*C21),"") | P29: =IFERROR(IF(OR(C21="",E21=0),"",E21*C21),"") | Q29: =IFERROR(IF(OR(C21="",F21=0),"",F21*C21),"") | R29: =IFERROR(IF(OR(C21="",G21=0),"",G21*C21),"") | S29: =IFERROR(IF(OR(C21="",H21=0),"",H21*C21),"") | T29: =IFERROR(IF(OR(C21="",I21=0),"",I21*C21),"") | U29: =IFERROR(IF(OR(C21="",J21=0),"",J21*C21),"") | V29: =IFERROR(IF(OR(C21="",K21=0),"",K21*C21),"") | W29: =IFERROR(IF(OR(C21="",L21=0),"",L21*C21),"")
C30: =IFERROR(INDEX('🧗 Climbing Log'!$B$75:$B$80,MATCH(B22,'🧗 Climbing Log'!$A$75:$A$80,0)),"") | M30: =IFERROR(SUM(E22:L22),0) | N30: =IFERROR(IF(OR(C22="",M22=0),"",M22*C22),"") | P30: =IFERROR(IF(OR(C22="",E22=0),"",E22*C22),"") | Q30: =IFERROR(IF(OR(C22="",F22=0),"",F22*C22),"") | R30: =IFERROR(IF(OR(C22="",G22=0),"",G22*C22),"") | S30: =IFERROR(IF(OR(C22="",H22=0),"",H22*C22),"") | T30: =IFERROR(IF(OR(C22="",I22=0),"",I22*C22),"") | U30: =IFERROR(IF(OR(C22="",J22=0),"",J22*C22),"") | V30: =IFERROR(IF(OR(C22="",K22=0),"",K22*C22),"") | W30: =IFERROR(IF(OR(C22="",L22=0),"",L22*C22),"")
C31: =IFERROR(INDEX('🧗 Climbing Log'!$B$75:$B$80,MATCH(B23,'🧗 Climbing Log'!$A$75:$A$80,0)),"") | M31: =IFERROR(SUM(E23:L23),0) | N31: =IFERROR(IF(OR(C23="",M23=0),"",M23*C23),"") | P31: =IFERROR(IF(OR(C23="",E23=0),"",E23*C23),"") | Q31: =IFERROR(IF(OR(C23="",F23=0),"",F23*C23),"") | R31: =IFERROR(IF(OR(C23="",G23=0),"",G23*C23),"") | S31: =IFERROR(IF(OR(C23="",H23=0),"",H23*C23),"") | T31: =IFERROR(IF(OR(C23="",I23=0),"",I23*C23),"") | U31: =IFERROR(IF(OR(C23="",J23=0),"",J23*C23),"") | V31: =IFERROR(IF(OR(C23="",K23=0),"",K23*C23),"") | W31: =IFERROR(IF(OR(C23="",L23=0),"",L23*C23),"")
C32: =IFERROR(INDEX('🧗 Climbing Log'!$B$75:$B$80,MATCH(B24,'🧗 Climbing Log'!$A$75:$A$80,0)),"") | M32: =IFERROR(SUM(E24:L24),0) | N32: =IFERROR(IF(OR(C24="",M24=0),"",M24*C24),"") | P32: =IFERROR(IF(OR(C24="",E24=0),"",E24*C24),"") | Q32: =IFERROR(IF(OR(C24="",F24=0),"",F24*C24),"") | R32: =IFERROR(IF(OR(C24="",G24=0),"",G24*C24),"") | S32: =IFERROR(IF(OR(C24="",H24=0),"",H24*C24),"") | T32: =IFERROR(IF(OR(C24="",I24=0),"",I24*C24),"") | U32: =IFERROR(IF(OR(C24="",J24=0),"",J24*C24),"") | V32: =IFERROR(IF(OR(C24="",K24=0),"",K24*C24),"") | W32: =IFERROR(IF(OR(C24="",L24=0),"",L24*C24),"")
... C64: =IFERROR(INDEX('🧗 Climbing Log'!$B$75:$B$80,MATCH(B56,'🧗 Climbing Log'!$A$75:$A$80,0)),"") | M64: =IFERROR(SUM(E56:L56),0) | N64: =IFERROR(IF(OR(C56="",M56=0),"",M56*C56),"") | P64: =IFERROR(IF(OR(C56="",E56=0),"",E56*C56),"") | Q64: =IFERROR(IF(OR(C56="",F56=0),"",F56*C56),"") | R64: =IFERROR(IF(OR(C56="",G56=0),"",G56*C56),"") | S64: =IFERROR(IF(OR(C56="",H56=0),"",H56*C56),"") | T64: =IFERROR(IF(OR(C56="",I56=0),"",I56*C56),"") | U64: =IFERROR(IF(OR(C56="",J56=0),"",J56*C56),"") | V64: =IFERROR(IF(OR(C56="",K56=0),"",K56*C56),"") | W64: =IFERROR(IF(OR(C56="",L56=0),"",L56*C56),"")
M65: =IFERROR(SUM(E57:L57),0) | N65: =IFERROR(IF(OR(C57="",M57=0),"",M57*C57),"") | P65: =IFERROR(IF(OR(C57="",E57=0),"",E57*C57),"") | Q65: =IFERROR(IF(OR(C57="",F57=0),"",F57*C57),"") | R65: =IFERROR(IF(OR(C57="",G57=0),"",G57*C57),"") | S65: =IFERROR(IF(OR(C57="",H57=0),"",H57*C57),"") | T65: =IFERROR(IF(OR(C57="",I57=0),"",I57*C57),"") | U65: =IFERROR(IF(OR(C57="",J57=0),"",J57*C57),"") | V65: =IFERROR(IF(OR(C57="",K57=0),"",K57*C57),"") | W65: =IFERROR(IF(OR(C57="",L57=0),"",L57*C57),"")
M66: =IFERROR(SUM(E58:L58),0) | N66: =IFERROR(IF(OR(C58="",M58=0),"",M58*C58),"") | P66: =IFERROR(IF(OR(C58="",E58=0),"",E58*C58),"") | Q66: =IFERROR(IF(OR(C58="",F58=0),"",F58*C58),"") | R66: =IFERROR(IF(OR(C58="",G58=0),"",G58*C58),"") | S66: =IFERROR(IF(OR(C58="",H58=0),"",H58*C58),"") | T66: =IFERROR(IF(OR(C58="",I58=0),"",I58*C58),"") | U66: =IFERROR(IF(OR(C58="",J58=0),"",J58*C58),"") | V66: =IFERROR(IF(OR(C58="",K58=0),"",K58*C58),"") | W66: =IFERROR(IF(OR(C58="",L58=0),"",L58*C58),"")
C67: =IFERROR(INDEX('🧗 Climbing Log'!$B$75:$B$80,MATCH(B59,'🧗 Climbing Log'!$A$75:$A$80,0)),"") | M67: =IFERROR(SUM(E59:L59),0) | N67: =IFERROR(IF(OR(C59="",M59=0),"",M59*C59),"") | P67: =IFERROR(IF(OR(C59="",E59=0),"",E59*C59),"") | Q67: =IFERROR(IF(OR(C59="",F59=0),"",F59*C59),"") | R67: =IFERROR(IF(OR(C59="",G59=0),"",G59*C59),"") | S67: =IFERROR(IF(OR(C59="",H59=0),"",H59*C59),"") | T67: =IFERROR(IF(OR(C59="",I59=0),"",I59*C59),"") | U67: =IFERROR(IF(OR(C59="",J59=0),"",J59*C59),"") | V67: =IFERROR(IF(OR(C59="",K59=0),"",K59*C59),"") | W67: =IFERROR(IF(OR(C59="",L59=0),"",L59*C59),"")
C68: =IFERROR(INDEX('🧗 Climbing Log'!$B$75:$B$80,MATCH(B60,'🧗 Climbing Log'!$A$75:$A$80,0)),"") | M68: =IFERROR(SUM(E60:L60),0) | N68: =IFERROR(IF(OR(C60="",M60=0),"",M60*C60),"") | P68: =IFERROR(IF(OR(C60="",E60=0),"",E60*C60),"") | Q68: =IFERROR(IF(OR(C60="",F60=0),"",F60*C60),"") | R68: =IFERROR(IF(OR(C60="",G60=0),"",G60*C60),"") | S68: =IFERROR(IF(OR(C60="",H60=0),"",H60*C60),"") | T68: =IFERROR(IF(OR(C60="",I60=0),"",I60*C60),"") | U68: =IFERROR(IF(OR(C60="",J60=0),"",J60*C60),"") | V68: =IFERROR(IF(OR(C60="",K60=0),"",K60*C60),"") | W68: =IFERROR(IF(OR(C60="",L60=0),"",L60*C60),"")
C69: =IFERROR(INDEX('🧗 Climbing Log'!$B$75:$B$80,MATCH(B61,'🧗 Climbing Log'!$A$75:$A$80,0)),"") | M69: =IFERROR(SUM(E61:L61),0) | N69: =IFERROR(IF(OR(C61="",M61=0),"",M61*C61),"") | P69: =IFERROR(IF(OR(C61="",E61=0),"",E61*C61),"") | Q69: =IFERROR(IF(OR(C61="",F61=0),"",F61*C61),"") | R69: =IFERROR(IF(OR(C61="",G61=0),"",G61*C61),"") | S69: =IFERROR(IF(OR(C61="",H61=0),"",H61*C61),"") | T69: =IFERROR(IF(OR(C61="",I61=0),"",I61*C61),"") | U69: =IFERROR(IF(OR(C61="",J61=0),"",J61*C61),"") | V69: =IFERROR(IF(OR(C61="",K61=0),"",K61*C61),"") | W69: =IFERROR(IF(OR(C61="",L61=0),"",L61*C61),"")
C70: =IFERROR(INDEX('🧗 Climbing Log'!$B$75:$B$80,MATCH(B62,'🧗 Climbing Log'!$A$75:$A$80,0)),"") | M70: =IFERROR(SUM(E62:L62),0) | N70: =IFERROR(IF(OR(C62="",M62=0),"",M62*C62),"") | P70: =IFERROR(IF(OR(C62="",E62=0),"",E62*C62),"") | Q70: =IFERROR(IF(OR(C62="",F62=0),"",F62*C62),"") | R70: =IFERROR(IF(OR(C62="",G62=0),"",G62*C62),"") | S70: =IFERROR(IF(OR(C62="",H62=0),"",H62*C62),"") | T70: =IFERROR(IF(OR(C62="",I62=0),"",I62*C62),"") | U70: =IFERROR(IF(OR(C62="",J62=0),"",J62*C62),"") | V70: =IFERROR(IF(OR(C62="",K62=0),"",K62*C62),"") | W70: =IFERROR(IF(OR(C62="",L62=0),"",L62*C62),"")
A73: 🏢 GYM REFERENCE TABLE — edit gym names and wall heights here
A74: Gym Name | B74: Wall Height (m) | C74: Notes
...

Sheet 🏔️ Climbing Goals
A1: 🏔️ Climbing Goals & Macrocycle — Peak: October 2025
A3: Lattice Assessment (May 2024)
A4: Body Mass | B4: 48.9 kg
A5: Side Split | B5: 160 cm
A6: Pull-ups 2 rep | B6: 12 kg
A7: 2-Arm Hang | B7: 44 kg (7'' × 8 sets)
A8: Repeaters | B8: 22 reps (+7 kg, RPE 10/10)
A9: OS Level | B9: 6a+ / 6b
A11: Lattice Update — January 2026
A12: Body Mass | B12: 49.3 kg ↑ from 48.9 | C12: RP Target | D12: Boulder | E12: Points | F12: Status
A13: Side Split | B13: 154 cm (heel-heel) | C13: 1× | D13: 7b+ | E13: 1 | F13: Project
A14: Pull-ups 2-rep | B14: 48.5 kg bw @ 95% RPE | C14: 1× | D14: 7a+ | E14: 1 | F14: Goal
A15: One-Arm Hang | B15: 19 rep × 190 sec (+7 kg) | C15: 2× | D15: 6c+ | E15: 2 | F15: Target
A16: Sport OS | B16: 6c+ ↑ from 6a+/6b 🎯 | C16: 4× | D16: 6b+ | E16: 4 | F16: Build
A17: Sport RP target | B17: 7a | C17: 8× | D17: 6a+ | E17: 8 | F17: Base
A18: Boulder OS | B18: V4 (6a+) | C18: 16× | D18: 5c+ | E18: 16 | F18: Warm-up
A19: Boulder RP target | B19: V5 | C19: 32× | D19: 5b | E19: 32 | F19: Volume
A21: 2026 Grade Pyramid Targets (updated)
A22: Grade | B22: OS Target 2026 | C22: RP Target 2026 | D22: Status 2026 | E22: Intensity | F22: Fatigue
A23: 7b–7b+ | C23: 1× | D23: Project 2026 | E23: Low | F23: Moderate
A24: 7a–7a+ | B24: 1× | C24: 2× | D24: RP Target ↑ | E24: Mod–High | F24: High
A25: 6c–6c+ | B25: 2× | C25: 4× | D25: Build (OS now here!) | E25: High | F25: Moderate
A26: 6b–6b+ | B26: 4× | C26: 8× | D26: Solid base | E26: High | F26: Low
A27: 6a–6a+ | B27: 8× | C27: 16× | D27: Warm-up zone | E27: High | F27: Low–Mod
A28: 5c–5c+ | B28: 16× | C28: 20× | D28: Volume | E28: High | F28: Low

Sheet 📅 Weekly Planner
A1: 📅 Weekly Training Planner — duplicate rows for each week
A3: Week Of | B3: Day | C3: Training Type | D3: Planned | E3: Actual Done | F3: Duration (min) | G3: RPE (1–10) | H3: Notes
A4: WEEK START DATE | B4: Monday | C4: Gym | D4: Inferior Members + Core
A5: WEEK START DATE | B5: Tuesday | C5: Climbing | D5: Technique + Volume (5c–6b+)
A6: WEEK START DATE | B6: Wednesday | C6: Rest / Walk | D6: Easy recovery
A7: WEEK START DATE | B7: Thursday | C7: Gym | D7: Superior + Wrist + Fingers
A8: WEEK START DATE | B8: Friday | C8: Rest
A9: WEEK START DATE | B9: Saturday | C9: Climbing | D9: Projects + Strength
A10: WEEK START DATE | B10: Sunday | C10: Rest | D10: Stretching
A12: ↓ ADD FUTURE WEEKS BELOW ↓
