Workbook

Sheet Graph Eval
B2: Name: | C2: =Goals!C2 -> 0
B3: Age: | C3: ='Self-Assement Test'!C3 -> 45
B4: Date: | C4: ='Self-Assement Test'!C4 -> 44823
B6: Experience | C6: ='Climbing Experience Eval'!C40 -> 25
B7: Technique | C7: =TecniSkills!C39 -> 18
B8: Mind | C8: ='Mental Skill Eval'!C39 -> 18
B9: Gen.Fitness | C9: ='General fitness Eval'!C39 -> 16
B10: Sports spec. | C10: ='Climbing specific Fitn'!C39 -> 18
B11: Injury risk | C11: ='Injury Risk Eval'!C39 -> 24
B12: Nutrition | C12: ='Nutritional Eval'!C39 -> 15
B13: Lifestyle | C13: ='Lifestyle Eval'!C39 -> 20

Sheet Goals
B2: Name:
B3: Age:
B4: Date:
A6: 1 | B6: Goal Setting
A7: a) | B7: Short-term goal
B8: i) | C8: What I want:
B9: ii) | C9: What will I sacrifice:
B10: iii) | C10: What I am going to do for it:
B11: Timelines:
A13: b) | B13: Medium-Term goal (in the calendar)
B14: i) | C14: Climbing projects, trips, comp
B15: ii) | C15: Non climbing
B16: iii) | C16: Outside climbing, social, etc
C17: Timelines:
A19: c) | B19: Long-term Goal
B20: i)
B21: ii)
B22: iii)

Sheet Self-Assement Test
B2: Name: | C2: Jo
B3: Age: | C3: 45
B4: Date: | C4: 44823
B5: (Score yourself between 1 and 5 on the follow questions) | H5: 1: almost always
H6: 2: often
H7: 3: sometimes
H8: 4: seldom
H9: 5: never
L10: Score (1-5)
A11: 1 | B11: I get anxiuous and tight as I head into crux sequences | L11: 2
A12: 2 | B12: I miss hidden holds | L12: 3
A13: 3 | B13: I have difficulty hanging on small, necessary-to-use holds | L13: 3
A14: 4 | B14: I make excuses for why I might fail on a route before I even begin to climb | L14: 4
A15: 5 | B15: My forearms ballon and my grip begins to fail even on routes that are easy for me | L15: 3
A16: 6 | B16: On hard sequences, I have difficulty stepping onto critical footholds | L16: 3
A17: 7 | B17: My footwork deteriorates during the hardes part of a climb | L17: 3
A18: 8 | B18: I pump out on overhanging climbs no matter how big the holds | L18: 4
A19: 9 | B19: I train or climb (or do a combination) three days in a row | L19: 5
A20: 10 | B20: I grab quickdraws, the rope, or other gear instead of risking a fall trying a hard move which i am unsure | L20: 5
A21: 11 | B21: I have difficulty in reading sequences | L21: 4
A22: 12 | B22: I experience shoulder, elbow, or finger oain when I climb | L22: 4
... A25: 15 | B25: I have difficulty hanging on to a small sloping holds or pockets | L25: 3
B27: Calculate your score in the three areas:
B28: Mental | C28: =(L11+L14+L17+L20+L23) -> 17
B29: Technical | C29: =(L12+L15+L18+L21+L24) -> 18
B30: Physical | C30: =(L13+L16+L19+L22+L25) -> 18

Sheet Climbing Experience Eval
B2: Name: | C2: =Goals!C2 -> 0
B3: Age: | C3: ='Self-Assement Test'!C3 -> 45
B4: Date: | C4: ='Self-Assement Test'!C4 -> 44823
B5: (Score yourself between 1 and 5 on the follow questions)
A8: 1 | B8: How long have you been climbing? | J8: R1 | K8: 5
B9: 1: less than six months
B10: 2: six to twelve months
B11: 3: one to four years
B12: 4: five to ten years
B13: 5: more than tem years
A14: 2 | B14: On average, how many days poer month do you climb (both indoor, outdoor)? | J14: R2 | K14: 5
B15: 1: one day or less
B16: 2: two to three days
B17: 3: four to eight days
B18: 4: nine to twelve days
B19: 5: more than twelve days
A20: 3 | B20: How many different climbing areas and gyms have you visited in the last year? | J20: R3 | K20: 10
B21: 1: just one
B22: 2: two to four
B23: 3: five to nine
B24: 4: ten to fifteen
B25: 5: more than fifteen
A26: 4 | B26: How many of the following styles of climbing have you been active in the last year, outdoor sports climbing, follow trad climb, lead trad climb, big walls? | Q26: R4 | R26: 3
B27: 1: one
B28: 2: two
B29: 3: three
B30: 4: four
B31: 5: five or six
A32: 5 | B32: How many of the following styles of climbing have you engaged in over the last three months: Slab climbing, face climbing, pocket climbing, roofs? | Q32: R5 | R32: 2
B33: 1: one or two
B34: 2: three
B35: 3: four to eight days
B36: 4: five to ten years
B37: 5: six
B40: Analyses: | C40: =R32+R26+K20+K14+K8 -> 25
B41: If:
B42: 23-25: you have excellent tecnhical skills
B43: 20-22: your technical skills are above average
B44: 15-19: Your tecnhicalskills are near average.
B45: 10-14: you possess some fundamental flaws in climbing technique
...

Sheet TecniSkills
B2: Name: | C2: =Goals!C2 -> 0
B3: Age: | C3: ='Self-Assement Test'!C3 -> 45
B4: Date: | C4: ='Self-Assement Test'!C4 -> 44823
B5: (Score yourself between 1 and 5 on the follow questions)
A7: 1 | B7: My footwork and overall technique detiorate during the hardest part of a climb. | L7: R1 | M7: 3
B8: 1: almost always
B9: 2: often
B10: 3:about half of the time
B11: 4: occasionally
B12: 5: seldom or never
A13: 2 | B13: Cracks, slabs, and roofs feel hard for the grade compared with a similiraty graded face climb. | L13: R2 | M13: 4
B14: 1: almost always
B15: 2: often
B16: 3:about half of the time
B17: 4: occasionally
B18: 5: seldom or never
A19: 3 | B19: I have difficulty finding mid-route rest positions and shakeouts. | L19: R3 | M19: 4
B20: 1: almost always
B21: 2: often
B22: 3:about half of the time
B23: 4: occasionally
B24: 5: seldom or never
A25: 4 | B25: On the typical climb, I feel like much my body weight is hanging on my arms. | L25: R4 | M25: 4
B26: 1: almost always
B27: 2: often
B28: 3:about half of the time
B29: 4: occasionally
B30: 5: seldom or never
A31: 5 | B31: On overhanging routes and roofs, I have difficulty finding the optimal body position or keeping my feet from cutting loose. | L31: R5 | M31: 3
B32: 1: almost always
B33: 2: often
B34: 3:about half of the time
B35: 4: occasionally
B36: 5: seldom or never
B39: Analyses: | C39: =M31+M25+M19+M13+M7 -> 18
B40: If:
B41: 23-25: you have excellent technical skills
B42: 20-22: your technical skills are above average
B43: 15-19: Your technical skills are near average.
B44: 10-14: you have limited technical skills and they are blocking your climbing performance.
...

Sheet Mental Skill Eval
B2: Name: | C2: =Goals!C2 -> 0
B3: Age: | C3: ='Self-Assement Test'!C3 -> 45
B4: Date: | C4: ='Self-Assement Test'!C4 -> 44823
B5: (Score yourself between 1 and 5 on the follow questions)
A7: 1 | B7: I visualize myself succesfully climbing the route before I leave the ground. | L7: R1 | M7: 3
B8: 1: seldom or never
B9: 2: occasionally
B10: 3:about half of the time
B11: 4: often
B12: 5: almost always
A13: 2 | B13: I get anxious, tight, and hesitant as I climb into crux sequences? | L13: R2 | M13: 3
B14: 1: almost always
B15: 2: often
B16: 3:about half of the time
B17: 4: occasionally
B18: 5: seldom or never
A19: 3 | B19: I miss hidden holds or blow a known sequence. | L19: R3 | M19: 4
B20: 1: almost always
B21: 2: often
B22: 3:about half of the time
B23: 4: occasionally
B24: 5: seldom or never
A25: 4 | B25: I make excuses for why I might fail on a route before I even begin to climb. | L25: R4 | M25: 3
B26: 1: almost always
B27: 2: often
B28: 3:about half of the time
B29: 4: occasionally
B30: 5: seldom or never
A31: 5 | B31: When I lead climb a safe route, I push myself to the complete limit, and if I fall, I fall trying. | L31: R5 | M31: 5
B32: 1: seldom or never
B33: 2: occasionally
B34: 3:about half of the time
B35: 4: often
B36: 5: almost always
B39: Analyses: | C39: =M31+M25+M19+M13+M7 -> 18
B40: If:
B41: 23-25: you have excellent mental skills
B42: 20-22: your mental skills are above average
B43: 15-19: Your mental skills are near average.
B44: 10-14: you have limited mental skills and they are blocking your climbing performance.
...

Sheet General fitness Eval
O1: DATE: | R1: DATE:
B2: Name: | C2: =Goals!C2 -> 0 | O2: 44823 | R2: 44909
B3: Age: | C3: ='Self-Assement Test'!C3 -> 45
B4: Date: | C4: ='Self-Assement Test'!C4 -> 44823 | J4: =50-48 -> 2
B5: (Score yourself between 1 and 5 on the follow questions)
A7: 1 | B7: How many kg (body fat or excessively bulky muscles) do you estimate you are from your Ideal climbing weight? | N7: R1 | O7: 4 | Q7: R1 | R7: 4
B8: 1: more then 4,5kg
B9: 2: 4,5kg - 9kg
B10: 3: 2,5kg - 4,5kg
B11: 4: just a few
B12: 5: 0kg
A13: 2 | B13: How far could you jog (modest-paced steady running) without stopping? | N13: R2 | O13: 3 | Q13: R2 | R13: 4
B14: 1: less then 800m
B15: 2: 800m to 1km
B16: 3:1km to 2,3km
B17: 4: 4,8km to 8km
B18: 5: more then 8km
A19: 3 | B19: How many pull-ups can you do in a single set? | N19: R3 | O19: 3 | Q19: R3 | R19: 3
B20: 1: W: one or none; M: less then five
B21: 2: W: two or four; M: five to nine
B22: 3: W: five to nine; M: ten to nineteen
B23: 4: W: ten to twenty; M: twenty to thirty
B24: 5: W: more then twenty; M: more then thirty
A25: 4 | B25: How many push-ups can you do in a single set? | N25: R4 | O25: 3 | Q25: R4 | R25: 4
B26: 1: W: less then two; M: less then five
B27: 2: W: three to six; M: five to fifteen
B28: 3: W: seven to fifteen; M: sixteen to twenty-five
B29: 4: W: sixteen to twenty-five; M: twenty-five to forty
B30: 5: W: more then twenty; M: more then forty
A31: 5 | B31: How many abdominal crunches can you do in a single set? | N31: R5 | O31: 3 | Q31: R5 | R31: 3
B32: 1: fewer then tem
B33: 2: ten to twenty
B34: 3: twenty-one to forty-nine
B35: 4: fifty to seventy-five
B36: 5: more then seventy-five
C38: =O2 -> 44823 | D38: =R2 -> 44909
B39: Analyses: | C39: =O31+O25+O19+O13+O7 -> 16 | D39: =R31+R25+R19+R13+R7 -> 18
B40: If:
B41: 23-25: you have excellent general fitness skills
B42: 20-22: your general fitness are above average
...

Sheet Climbing specific Fitn
B2: Name: | C2: =Goals!C2 -> 0
B3: Age: | C3: ='Self-Assement Test'!C3 -> 45
B4: Date: | C4: ='Self-Assement Test'!C4 -> 44823
B5: (Score yourself between 1 and 5 on the follow questions)
A7: 1 | B7: On overhang routes with large holds, I pump out quickly and need to hang on the rope. | L7: R1 | M7: 4
B8: 1: almost always
B9: 2: often
B10: 3:about half of the time
B11: 4: occasionally
B12: 5: seldom or never
A13: 2 | B13: I have difficulty hanging on small, necessary-to-use holds | L13: R2 | M13: 4
B14: 1: almost always
B15: 2: often
B16: 3:about half of the time
B17: 4: occasionally
B18: 5: seldom or never
A19: 3 | B19: I find it difficult to hold a lock-off with one arm when I get to advance the other hand | L19: R3 | M19: 3
B20: 1: almost always
B21: 2: often
B22: 3:about half of the time
B23: 4: occasionally
B24: 5: seldom or never
A25: 4 | B25: Given a marginal mid-climb rest, I can shake out and recover enough to complete the route. | L25: R4 | M25: 4
B26: 1: seldom or never
B27: 2: occasionally
B28: 3:about half of the time
B29: 4: often
B30: 5: almost always
A31: 5 | B31: My maximum bouldering hability is: | L31: R5 | M31: 3
B32: 1: V0 or V1
B33: 2: V2 to V3
B34: 3: V4 to V6
B35: 4: V7 to V9
B36: 5: V10 above
B39: Analyses: | C39: =M31+M25+M19+M13+M7 -> 18
B40: If:
B41: 23-25: you have excellent climbing fitness skills
B42: 20-22: your climbing fitness are above average
B43: 15-19: Your climbing fitness are near average.
B44: 10-14: you have limited climbing fitness and they are blocking your climbing performance.
...

Sheet Injury Risk Eval
B2: Name: | C2: =Goals!C2 -> 0
B3: Age: | C3: ='Self-Assement Test'!C3 -> 45
B4: Date: | C4: ='Self-Assement Test'!C4 -> 44823
B5: (Score yourself between 1 and 5 on the follow questions)
A7: 1 | B7: I perform warm-up activity and some stretching before climbing or training. | L7: R1 | M7: 5
B8: 1: seldom or never
B9: 2: occasionally
B10: 3:about half of the time
B11: 4: often
B12: 5: almost always
A13: 2 | B13: I climb hard on three or more consecutive days. | L13: R2 | M13: 5
B14: 1: every week
B15: 2: often
B16: 3:a couple of times per month
B17: 4: once per month
B18: 5: seldom or never
A19: 3 | B19: When climbing, I experience elbow, shoulder, or finger pain. | L19: R3 | M19: 5
B20: 1: almost always
B21: 2: often
B22: 3: occasionally
B23: 4: frequently
B24: 5: never
A25: 4 | B25: I engage in regular training of the antagonist and stabilizer muscles. | L25: R4 | M25: 5
B26: 1: never
B27: 2: occasionally
B28: 3: a few time a month
B29: 4: once or twice a week
B30: 5: always twice a week
A31: 5 | B31: I stop climbing or end a workout prematurely if I experienc unusual joint or tendon pain. | L31: R5 | M31: 4
B32: 1: never
B33: 2: occasionally
B34: 3: about half of the time
B35: 4: often
B36: 5: always
B39: Analyses: | C39: =M31+M25+M19+M13+M7 -> 24
B40: If:
B41: 23-25: Congratulations, you have a good injury awerness!
B42: 20-22: you are in the good way to avoid climbing injuries.
B43: 15-19: Your are at near average climbing injury. Warm up, recovery and stabelizer muscle training.
B44: 10-14: Your are at above average risk of climbing injury. Warm up, recovery and stabelizer muscle training.
...

Sheet Nutritional  Eval
B2: Name: | C2: =Goals!C2 -> 0
B3: Age: | C3: ='Self-Assement Test'!C3 -> 45
B4: Date: | C4: ='Self-Assement Test'!C4 -> 44823
B5: (Score yourself between 1 and 5 on the follow questions)
A7: 1 | B7: How often you eat breakfast? | N7: R1 | O7: 5
B8: 1: seldom or never
B9: 2: weekends only
B10: 3:three days a week
B11: 4: five days a week
B12: 5: every day
A13: 2 | B13: How often do you eat food or fried food? | N13: R2 | O13: 3
B14: 1: four or more days a week
B15: 2: two to three days a week
B16: 3: once a week
B17: 4: once or twice per month
B18: 5: less then once per month
A19: 3 | B19: On average, how soon after workout or the end of your climbing day, do you consume come Carbs and Protein? | N19: R3 | O19: 3
B20: 1: more then 3 hours
B21: 2: 2hr to 3 hrs
B22: 3: 1hr to 2hr
B23: 4: 30min to 1hr
B24: 5: within 30min
A25: 4 | B25: How many servings of fruit and vegetables do you consume per day? | N25: R4 | O25: 3
B26: 1: less then one
B27: 2: two
B28: 3: three
B29: 4: four
B30: 5: more then five
A31: 5 | B31: How often do you plan your out your meals ahead of time for the purpose of eating for performance and optimal recovery? | N31: R5 | O31: 1
B32: 1: seldom or never
B33: 2: once per week
B34: 3: two to three days a week
B35: 4: fourtor six days a week
B36: 5: every day
B39: Analyses: | C39: =O31+O25+O19+O13+O7 -> 15
B40: If:
B41: 23-25: Congratulations, you have a good nutritional awerness!
B42: 20-22: you are in the good way to a good nutritional awereness
B43: 15-19: Your are at near average of nutritional awerness.
B44: 10-14: Your are at above average of nutritional awereness
...

Sheet Lifestyle Eval
B2: Name: | C2: =Goals!C2 -> 0
B3: Age: | C3: ='Self-Assement Test'!C3 -> 45
B4: Date: | C4: ='Self-Assement Test'!C4 -> 44823
B5: (Score yourself between 1 and 5 on the follow questions)
A7: 1 | B7: How many days per week do you engage ia a physical actgivity such climbing or other sport? | N7: R1 | O7: 5
B8: 1: one
B9: 2: two
B10: 3:three
B11: 4: four
B12: 5: five
A13: 2 | B13: On average, how many hours of sleep do you get each night? | N13: R2 | O13: 3
B14: 1: less the five
B15: 2: five to six
B16: 3: six to seven
B17: 4: seven to eight
B18: 5: more then eight
A19: 3 | B19: How often do you pig out eating and drinking with litle restrain? | N19: R3 | O19: 3
B20: 1: three or more days a week
B21: 2: twice per week
B22: 3: once per week
B23: 4: once or twice per month
B24: 5: seldom or never
A25: 4 | B25: Do you smoke? | N25: R4 | O25: 5
B26: 1: yes, a half a pack a day
B27: 2: yes, but only a few smokes per day
B28: 3: yes but not daily - only few times a week
B29: 4: I have quit
B30: 5: I have never smoked
A31: 5 | B31: When you set goals or begin a workout program, how often do you follow through to successful completion? | N31: R5 | O31: 4
B32: 1: seldom
B33: 2: occasionally
B34: 3: about half the time
B35: 4: often
B36: 5: almost always
B39: Analyses: | C39: =O31+O25+O19+O13+O7 -> 20
B40: If:
B41: 23-25: You are higly disciplined individual!
B42: 20-22: Your discipline is above average.
B43: 15-19: Your are at near average.
B44: 10-14: Your are at above average. Determine priorities!
...
